Workbook

Sheet Brody
A1: 0.0001 | B1: ='0.0001'!$H$1 -> 0.086635423
A2: 0.001 | B2: ='0.001'!$H$1 -> 0.093763644
A3: 0.005 | B3: ='0.005'!$H$1 -> 0.14356393
A4: 0.01 | B4: ='0.01'!$H$1 -> 0.1694028
A5: 0.025 | B5: ='0.025'!$H$1 -> 0.22286791
A6: 0.05 | B6: ='0.05'!$H$1 -> 0.27919095
A7: 0.075 | B7: ='0.075'!$H$1 -> 0.32379495
A8: 0.1 | B8: ='0.1'!$H$1 -> 0.36335414
A9: 0.15 | B9: ='0.15'!$H$1 -> 0.42941047
A10: 0.2 | B10: ='0.2'!$H$1 -> 0.49015118
A11: 0.25 | B11: ='0.25'!$H$1 -> 0.5498873
A12: 0.3 | B12: ='0.3'!$H$1 -> 0.61375793
A13: 0.35 | B13: ='0.35'!$H$1 -> 0.6737332
A14: 0.4 | B14: ='0.4'!$H$1 -> 0.74615308
A15: 0.45 | B15: ='0.45'!$H$1 -> 0.81942794
A16: 0.5 | B16: ='0.5'!$H$1 -> 0.90368189
A17: 0.55 | B17: ='0.55'!$H$1 -> 1.002267
A18: 0.6 | B18: ='0.6'!$H$1 -> 1.1165137
A19: 0.65 | B19: ='0.65'!$H$1 -> 1.2504989
A20: 0.7 | B20: ='0.7'!$H$1 -> 1.4223917
A21: 0.75 | B21: ='0.75'!$H$1 -> 1.6455456
A22: 0.8 | B22: ='0.8'!$H$1 -> 1.9468299
A23: 0.85 | B23: ='0.85'!$H$1 -> 2.3780224
A24: 0.9 | B24: ='0.9'!$H$1 -> 3.1294056
A25: 0.925 | B25: ='0.925'!$H$1 -> 3.7568034
A26: 0.95 | B26: ='0.95'!$H$1 -> 4.8121703
A27: 0.975 | B27: ='0.975'!$H$1 -> 7.2169384
A28: 0.99 | B28: ='0.99'!$H$1 -> 12.01698
A29: 0.995 | B29: ='0.995'!$H$1 -> 17.386985
A30: 0.999 | B30: ='0.999'!$H$1 -> 40.110174
A31: 0.9999 | B31: ='0.9999'!$H$1 -> 127.63186

Sheet 0.0001
A1: 0.070940651 | B1: 0.79466751 | C1: =$H$3*(1+$H$1)*(A1^($H$1))*EXP(-$H$3*(A1^(1+$H$1))) -> 0.79056375 | D1: =B1-C1 -> 0.004103761 | E1: =D1^2 -> 1.6840854e-05 | G1: b | H1: 0.086635423
A2: 0.21189657 | B2: 0.73707644 | C2: =$H$3*(1+$H$1)*(A2^($H$1))*EXP(-$H$3*(A2^(1+$H$1))) -> 0.76744311 | D2: =B2-C2 -> -0.030366672 | E2: =D2^2 -> 0.00092213479
A3: 0.35285249 | B3: 0.67814604 | C3: =$H$3*(1+$H$1)*(A3^($H$1))*EXP(-$H$3*(A3^(1+$H$1))) -> 0.7025509 | D3: =B3-C3 -> -0.024404867 | E3: =D3^2 -> 0.00059559752 | G3: a_b | H3: =(_xlfn.GAMMA((2+$H$1)/(1+$H$1)))^(1+$H$1) -> 0.96622099
A4: 0.49380841 | B4: 0.60359015 | C4: =$H$3*(1+$H$1)*(A4^($H$1))*EXP(-$H$3*(A4^(1+$H$1))) -> 0.63050027 | D4: =B4-C4 -> -0.026910116 | E4: =D4^2 -> 0.00072415436
A5: 0.63476433 | B5: 0.54421331 | C5: =$H$3*(1+$H$1)*(A5^($H$1))*EXP(-$H$3*(A5^(1+$H$1))) -> 0.55973365 | D5: =B5-C5 -> -0.015520338 | E5: =D5^2 -> 0.00024088089 | G5: SUM | H5: =SUM(E1:E40) -> 0.0081436989
A6: 0.77572025 | B6: 0.46206791 | C6: =$H$3*(1+$H$1)*(A6^($H$1))*EXP(-$H$3*(A6^(1+$H$1))) -> 0.49337536 | D6: =B6-C6 -> -0.031307458 | E6: =D6^2 -> 0.00098015691
A7: 0.91667617 | B7: 0.41117347 | C7: =$H$3*(1+$H$1)*(A7^($H$1))*EXP(-$H$3*(A7^(1+$H$1))) -> 0.43262896 | D7: =B7-C7 -> -0.021455488 | E7: =D7^2 -> 0.00046033795
A8: 1.0576321 | B8: 0.38929779 | C8: =$H$3*(1+$H$1)*(A8^($H$1))*EXP(-$H$3*(A8^(1+$H$1))) -> 0.37783365 | D8: =B8-C8 -> 0.011464145 | E8: =D8^2 -> 0.00013142662
A9: 1.198588 | B9: 0.33840335 | C9: =$H$3*(1+$H$1)*(A9^($H$1))*EXP(-$H$3*(A9^(1+$H$1))) -> 0.32889986 | D9: =B9-C9 -> 0.0095034956 | E9: =D9^2 -> 9.0316428e-05
A10: 1.3395439 | B10: 0.29197334 | C10: =$H$3*(1+$H$1)*(A10^($H$1))*EXP(-$H$3*(A10^(1+$H$1))) -> 0.28551978 | D10: =B10-C10 -> 0.0064535606 | E10: =D10^2 -> 4.1648444e-05
A11: 1.4804998 | B11: 0.25759728 | C11: =$H$3*(1+$H$1)*(A11^($H$1))*EXP(-$H$3*(A11^(1+$H$1))) -> 0.24727935 | D11: =B11-C11 -> 0.010317929 | E11: =D11^2 -> 0.00010645966
A12: 1.6214558 | B12: 0.22723919 | C12: =$H$3*(1+$H$1)*(A12^($H$1))*EXP(-$H$3*(A12^(1+$H$1))) -> 0.21372123 | D12: =B12-C12 -> 0.013517961 | E12: =D12^2 -> 0.00018273527
A13: 1.7624117 | B13: 0.18393428 | C13: =$H$3*(1+$H$1)*(A13^($H$1))*EXP(-$H$3*(A13^(1+$H$1))) -> 0.18438125 | D13: =B13-C13 -> -0.0004469702 | E13: =D13^2 -> 1.9978236e-07
A14: 1.9033676 | B14: 0.17411254 | C14: =$H$3*(1+$H$1)*(A14^($H$1))*EXP(-$H$3*(A14^(1+$H$1))) -> 0.15880939 | D14: =B14-C14 -> 0.01530315 | E14: =D14^2 -> 0.00023418641
A15: 2.0443235 | B15: 0.17723764 | C15: =$H$3*(1+$H$1)*(A15^($H$1))*EXP(-$H$3*(A15^(1+$H$1))) -> 0.13658165 | D15: =B15-C15 -> 0.040655993 | E15: =D15^2 -> 0.0016529098
A16: 2.1852794 | B16: 0.13348628 | C16: =$H$3*(1+$H$1)*(A16^($H$1))*EXP(-$H$3*(A16^(1+$H$1))) -> 0.11730606 | D16: =B16-C16 -> 0.016180223 | E16: =D16^2 -> 0.00026179961
A17: 2.3262354 | B17: 0.11830724 | C17: =$H$3*(1+$H$1)*(A17^($H$1))*EXP(-$H$3*(A17^(1+$H$1))) -> 0.10062528 | D17: =B17-C17 -> 0.017681958 | E17: =D17^2 -> 0.00031265165
... A40: 5.5682215 | B40: 0.00044644242 | C40: =$H$3*(1+$H$1)*(A40^($H$1))*EXP(-$H$3*(A40^(1+$H$1))) -> 0.0023682825 | D40: =B40-C40 -> -0.0019218401 | E40: =D40^2 -> 3.6934693e-06

Sheet 0.001
A1: 0.070658377 | B1: 0.77452447 | C1: =$H$3*(1+$H$1)*(A1^($H$1))*EXP(-$H$3*(A1^(1+$H$1))) -> 0.77961661 | D1: =B1-C1 -> -0.0050921329 | E1: =D1^2 -> 2.5929817e-05 | G1: b | H1: 0.093763644
A2: 0.21108346 | B2: 0.74854274 | C2: =$H$3*(1+$H$1)*(A2^($H$1))*EXP(-$H$3*(A2^(1+$H$1))) -> 0.76411522 | D2: =B2-C2 -> -0.015572481 | E2: =D2^2 -> 0.00024250217
A3: 0.35150853 | B3: 0.69254762 | C3: =$H$3*(1+$H$1)*(A3^($H$1))*EXP(-$H$3*(A3^(1+$H$1))) -> 0.70291623 | D3: =B3-C3 -> -0.010368609 | E3: =D3^2 -> 0.00010750806 | G3: a_b | H3: =(_xlfn.GAMMA((2+$H$1)/(1+$H$1)))^(1+$H$1) -> 0.96367405
A4: 0.49193361 | B4: 0.61057077 | C4: =$H$3*(1+$H$1)*(A4^($H$1))*EXP(-$H$3*(A4^(1+$H$1))) -> 0.63289498 | D4: =B4-C4 -> -0.022324215 | E4: =D4^2 -> 0.00049837059
A5: 0.63235869 | B5: 0.53576129 | C5: =$H$3*(1+$H$1)*(A5^($H$1))*EXP(-$H$3*(A5^(1+$H$1))) -> 0.56320863 | D5: =B5-C5 -> -0.027447344 | E5: =D5^2 -> 0.00075335669 | G5: SUM | H5: =SUM(E1:E40) -> 0.0066956528
A6: 0.77278377 | B6: 0.4667753 | C6: =$H$3*(1+$H$1)*(A6^($H$1))*EXP(-$H$3*(A6^(1+$H$1))) -> 0.49734328 | D6: =B6-C6 -> -0.030567975 | E6: =D6^2 -> 0.0009344011
A7: 0.91320885 | B7: 0.41570776 | C7: =$H$3*(1+$H$1)*(A7^($H$1))*EXP(-$H$3*(A7^(1+$H$1))) -> 0.4367186 | D7: =B7-C7 -> -0.02101084 | E7: =D7^2 -> 0.00044145541
A8: 1.0536339 | B8: 0.38748622 | C8: =$H$3*(1+$H$1)*(A8^($H$1))*EXP(-$H$3*(A8^(1+$H$1))) -> 0.38181287 | D8: =B8-C8 -> 0.005673342 | E8: =D8^2 -> 3.2186809e-05
A9: 1.194059 | B9: 0.34134624 | C9: =$H$3*(1+$H$1)*(A9^($H$1))*EXP(-$H$3*(A9^(1+$H$1))) -> 0.33262916 | D9: =B9-C9 -> 0.0087170777 | E9: =D9^2 -> 7.5987443e-05
A10: 1.3344841 | B10: 0.29834199 | C10: =$H$3*(1+$H$1)*(A10^($H$1))*EXP(-$H$3*(A10^(1+$H$1))) -> 0.28892213 | D10: =B10-C10 -> 0.0094198625 | E10: =D10^2 -> 8.8733809e-05
A11: 1.4749092 | B11: 0.25309793 | C11: =$H$3*(1+$H$1)*(A11^($H$1))*EXP(-$H$3*(A11^(1+$H$1))) -> 0.2503198 | D11: =B11-C11 -> 0.0027781361 | E11: =D11^2 -> 7.7180402e-06
A12: 1.6153342 | B12: 0.22846008 | C12: =$H$3*(1+$H$1)*(A12^($H$1))*EXP(-$H$3*(A12^(1+$H$1))) -> 0.21639283 | D12: =B12-C12 -> 0.012067254 | E12: =D12^2 -> 0.00014561862
A13: 1.7557593 | B13: 0.18455991 | C13: =$H$3*(1+$H$1)*(A13^($H$1))*EXP(-$H$3*(A13^(1+$H$1))) -> 0.18669512 | D13: =B13-C13 -> -0.0021352084 | E13: =D13^2 -> 4.559115e-06
A14: 1.8961844 | B14: 0.17470477 | C14: =$H$3*(1+$H$1)*(A14^($H$1))*EXP(-$H$3*(A14^(1+$H$1))) -> 0.1607878 | D14: =B14-C14 -> 0.01391697 | E14: =D14^2 -> 0.00019368204
A15: 2.0366095 | B15: 0.17604865 | C15: =$H$3*(1+$H$1)*(A15^($H$1))*EXP(-$H$3*(A15^(1+$H$1))) -> 0.13825312 | D15: =B15-C15 -> 0.03779553 | E15: =D15^2 -> 0.0014285021
A16: 2.1770346 | B16: 0.13797197 | C16: =$H$3*(1+$H$1)*(A16^($H$1))*EXP(-$H$3*(A16^(1+$H$1))) -> 0.11870204 | D16: =B16-C16 -> 0.019269927 | E16: =D16^2 -> 0.00037133007
A17: 2.3174596 | B17: 0.11781373 | C17: =$H$3*(1+$H$1)*(A17^($H$1))*EXP(-$H$3*(A17^(1+$H$1))) -> 0.10177784 | D17: =B17-C17 -> 0.016035888 | E17: =D17^2 -> 0.0002571497
... A40: 5.5472364 | B40: 0.00044796094 | C40: =$H$3*(1+$H$1)*(A40^($H$1))*EXP(-$H$3*(A40^(1+$H$1))) -> 0.0023249632 | D40: =B40-C40 -> -0.0018770023 | E40: =D40^2 -> 3.5231376e-06

Sheet 0.005
A1: 0.070477372 | B1: 0.6212619 | C1: =$H$3*(1+$H$1)*(A1^($H$1))*EXP(-$H$3*(A1^(1+$H$1))) -> 0.70682777 | D1: =B1-C1 -> -0.085565872 | E1: =D1^2 -> 0.0073215185 | G1: b | H1: 0.14356393
A2: 0.20978468 | B2: 0.86100758 | C2: =$H$3*(1+$H$1)*(A2^($H$1))*EXP(-$H$3*(A2^(1+$H$1))) -> 0.73823081 | D2: =B2-C2 -> 0.12277677 | E2: =D2^2 -> 0.015074136
A3: 0.34909199 | B3: 0.72420355 | C3: =$H$3*(1+$H$1)*(A3^($H$1))*EXP(-$H$3*(A3^(1+$H$1))) -> 0.70059798 | D3: =B3-C3 -> 0.023605566 | E3: =D3^2 -> 0.00055722274 | G3: a_b | H3: =(_xlfn.GAMMA((2+$H$1)/(1+$H$1)))^(1+$H$1) -> 0.94674433
A4: 0.4883993 | B4: 0.6194559 | C4: =$H$3*(1+$H$1)*(A4^($H$1))*EXP(-$H$3*(A4^(1+$H$1))) -> 0.64362368 | D4: =B4-C4 -> -0.024167777 | E4: =D4^2 -> 0.00058408145
A5: 0.62770661 | B5: 0.55489162 | C5: =$H$3*(1+$H$1)*(A5^($H$1))*EXP(-$H$3*(A5^(1+$H$1))) -> 0.58084121 | D5: =B5-C5 -> -0.025949585 | E5: =D5^2 -> 0.00067338099 | G5: SUM | H5: =SUM(E1:E40) -> 0.030762806
A6: 0.76701392 | B6: 0.46865541 | C6: =$H$3*(1+$H$1)*(A6^($H$1))*EXP(-$H$3*(A6^(1+$H$1))) -> 0.51804652 | D6: =B6-C6 -> -0.049391106 | E6: =D6^2 -> 0.0024394814
A7: 0.90632123 | B7: 0.41944208 | C7: =$H$3*(1+$H$1)*(A7^($H$1))*EXP(-$H$3*(A7^(1+$H$1))) -> 0.45807579 | D7: =B7-C7 -> -0.038633707 | E7: =D7^2 -> 0.0014925633
A8: 1.0456285 | B8: 0.38557969 | C8: =$H$3*(1+$H$1)*(A8^($H$1))*EXP(-$H$3*(A8^(1+$H$1))) -> 0.40233291 | D8: =B8-C8 -> -0.01675322 | E8: =D8^2 -> 0.00028067037
A9: 1.1849359 | B9: 0.34720232 | C9: =$H$3*(1+$H$1)*(A9^($H$1))*EXP(-$H$3*(A9^(1+$H$1))) -> 0.35144171 | D9: =B9-C9 -> -0.0042393831 | E9: =D9^2 -> 1.7972369e-05
A10: 1.3242432 | B10: 0.2948285 | C10: =$H$3*(1+$H$1)*(A10^($H$1))*EXP(-$H$3*(A10^(1+$H$1))) -> 0.30557539 | D10: =B10-C10 -> -0.010746887 | E10: =D10^2 -> 0.00011549557
A11: 1.4635505 | B11: 0.25961162 | C11: =$H$3*(1+$H$1)*(A11^($H$1))*EXP(-$H$3*(A11^(1+$H$1))) -> 0.26464162 | D11: =B11-C11 -> -0.0050300015 | E11: =D11^2 -> 2.5300915e-05
A12: 1.6028578 | B12: 0.22981272 | C12: =$H$3*(1+$H$1)*(A12^($H$1))*EXP(-$H$3*(A12^(1+$H$1))) -> 0.22839361 | D12: =B12-C12 -> 0.0014191161 | E12: =D12^2 -> 2.0138904e-06
A13: 1.7421651 | B13: 0.19188685 | C13: =$H$3*(1+$H$1)*(A13^($H$1))*EXP(-$H$3*(A13^(1+$H$1))) -> 0.19649954 | D13: =B13-C13 -> -0.0046126903 | E13: =D13^2 -> 2.1276912e-05
A14: 1.8814724 | B14: 0.18240538 | C14: =$H$3*(1+$H$1)*(A14^($H$1))*EXP(-$H$3*(A14^(1+$H$1))) -> 0.16858704 | D14: =B14-C14 -> 0.013818339 | E14: =D14^2 -> 0.0001909465
A15: 2.0207797 | B15: 0.17111792 | C15: =$H$3*(1+$H$1)*(A15^($H$1))*EXP(-$H$3*(A15^(1+$H$1))) -> 0.1442717 | D15: =B15-C15 -> 0.026846221 | E15: =D15^2 -> 0.00072071957
A16: 2.160087 | B16: 0.14041602 | C16: =$H$3*(1+$H$1)*(A16^($H$1))*EXP(-$H$3*(A16^(1+$H$1))) -> 0.12317526 | D16: =B16-C16 -> 0.017240765 | E16: =D16^2 -> 0.00029724399
A17: 2.2993943 | B17: 0.11468061 | C17: =$H$3*(1+$H$1)*(A17^($H$1))*EXP(-$H$3*(A17^(1+$H$1))) -> 0.1049369 | D17: =B17-C17 -> 0.0097437118 | E17: =D17^2 -> 9.493992e-05
... A40: 5.5034625 | B40: 0.00045149847 | C40: =$H$3*(1+$H$1)*(A40^($H$1))*EXP(-$H$3*(A40^(1+$H$1))) -> 0.0017793609 | D40: =B40-C40 -> -0.0013278624 | E40: =D40^2 -> 1.7632185e-06

Sheet 0.01
A1: 0.069798813 | B1: 0.58072228 | C1: =$H$3*(1+$H$1)*(A1^($H$1))*EXP(-$H$3*(A1^(1+$H$1))) -> 0.67054402 | D1: =B1-C1 -> -0.089821732 | E1: =D1^2 -> 0.0080679436 | G1: b | H1: 0.1694028
A2: 0.2081298 | B2: 0.81519231 | C2: =$H$3*(1+$H$1)*(A2^($H$1))*EXP(-$H$3*(A2^(1+$H$1))) -> 0.72427519 | D2: =B2-C2 -> 0.090917122 | E2: =D2^2 -> 0.0082659231
A3: 0.34646079 | B3: 0.77929477 | C3: =$H$3*(1+$H$1)*(A3^($H$1))*EXP(-$H$3*(A3^(1+$H$1))) -> 0.69890412 | D3: =B3-C3 -> 0.080390648 | E3: =D3^2 -> 0.0064626563 | G3: a_b | H3: =(_xlfn.GAMMA((2+$H$1)/(1+$H$1)))^(1+$H$1) -> 0.93851462
A4: 0.48479178 | B4: 0.64342939 | C4: =$H$3*(1+$H$1)*(A4^($H$1))*EXP(-$H$3*(A4^(1+$H$1))) -> 0.64915571 | D4: =B4-C4 -> -0.0057263235 | E4: =D4^2 -> 3.2790781e-05
A5: 0.62312277 | B5: 0.5707255 | C5: =$H$3*(1+$H$1)*(A5^($H$1))*EXP(-$H$3*(A5^(1+$H$1))) -> 0.59044974 | D5: =B5-C5 -> -0.019724239 | E5: =D5^2 -> 0.00038904561 | G5: SUM | H5: =SUM(E1:E40) -> 0.032098452
A6: 0.76145376 | B6: 0.47166646 | C6: =$H$3*(1+$H$1)*(A6^($H$1))*EXP(-$H$3*(A6^(1+$H$1))) -> 0.52965817 | D6: =B6-C6 -> -0.057991714 | E6: =D6^2 -> 0.0033630389
A7: 0.89978474 | B7: 0.42804413 | C7: =$H$3*(1+$H$1)*(A7^($H$1))*EXP(-$H$3*(A7^(1+$H$1))) -> 0.47032021 | D7: =B7-C7 -> -0.042276083 | E7: =D7^2 -> 0.0017872672
A8: 1.0381157 | B8: 0.38442179 | C8: =$H$3*(1+$H$1)*(A8^($H$1))*EXP(-$H$3*(A8^(1+$H$1))) -> 0.41432396 | D8: =B8-C8 -> -0.029902164 | E8: =D8^2 -> 0.00089413942
A9: 1.1764467 | B9: 0.35306824 | C9: =$H$3*(1+$H$1)*(A9^($H$1))*EXP(-$H$3*(A9^(1+$H$1))) -> 0.36263289 | D9: =B9-C9 -> -0.0095646477 | E9: =D9^2 -> 9.1482486e-05
A10: 1.3147777 | B10: 0.30353872 | C10: =$H$3*(1+$H$1)*(A10^($H$1))*EXP(-$H$3*(A10^(1+$H$1))) -> 0.31565864 | D10: =B10-C10 -> -0.012119922 | E10: =D10^2 -> 0.00014689251
A11: 1.4531087 | B11: 0.2558268 | C11: =$H$3*(1+$H$1)*(A11^($H$1))*EXP(-$H$3*(A11^(1+$H$1))) -> 0.27347434 | D11: =B11-C11 -> -0.017647542 | E11: =D11^2 -> 0.00031143572
A12: 1.5914397 | B12: 0.23810522 | C12: =$H$3*(1+$H$1)*(A12^($H$1))*EXP(-$H$3*(A12^(1+$H$1))) -> 0.23594546 | D12: =B12-C12 -> 0.0021597644 | E12: =D12^2 -> 4.6645824e-06
A13: 1.7297707 | B13: 0.1881213 | C13: =$H$3*(1+$H$1)*(A13^($H$1))*EXP(-$H$3*(A13^(1+$H$1))) -> 0.20281372 | D13: =B13-C13 -> -0.014692413 | E13: =D13^2 -> 0.00021586701
A14: 1.8681017 | B14: 0.1903933 | C14: =$H$3*(1+$H$1)*(A14^($H$1))*EXP(-$H$3*(A14^(1+$H$1))) -> 0.17375211 | D14: =B14-C14 -> 0.016641187 | E14: =D14^2 -> 0.00027692912
A15: 2.0064327 | B15: 0.17312613 | C15: =$H$3*(1+$H$1)*(A15^($H$1))*EXP(-$H$3*(A15^(1+$H$1))) -> 0.14840149 | D15: =B15-C15 -> 0.024724636 | E15: =D15^2 -> 0.00061130763
A16: 2.1447636 | B16: 0.13995498 | C16: =$H$3*(1+$H$1)*(A16^($H$1))*EXP(-$H$3*(A16^(1+$H$1))) -> 0.12639471 | D16: =B16-C16 -> 0.013560267 | E16: =D16^2 -> 0.00018388085
A17: 2.2830946 | B17: 0.11269102 | C17: =$H$3*(1+$H$1)*(A17^($H$1))*EXP(-$H$3*(A17^(1+$H$1))) -> 0.10737239 | D17: =B17-C17 -> 0.0053186294 | E17: =D17^2 -> 2.8287819e-05
... A40: 5.4647074 | B40: 0.00045439928 | C40: =$H$3*(1+$H$1)*(A40^($H$1))*EXP(-$H$3*(A40^(1+$H$1))) -> 0.0015684696 | D40: =B40-C40 -> -0.0011140703 | E40: =D40^2 -> 1.2411527e-06

Sheet 0.025
A1: 0.069278389 | B1: 0.56279718 | C1: =$H$3*(1+$H$1)*(A1^($H$1))*EXP(-$H$3*(A1^(1+$H$1))) -> 0.60071989 | D1: =B1-C1 -> -0.037922714 | E1: =D1^2 -> 0.0014381323 | G1: b | H1: 0.22286791
A2: 0.20518519 | B2: 0.61921563 | C2: =$H$3*(1+$H$1)*(A2^($H$1))*EXP(-$H$3*(A2^(1+$H$1))) -> 0.69392968 | D2: =B2-C2 -> -0.074714057 | E2: =D2^2 -> 0.0055821902
A3: 0.34109199 | B3: 0.83147849 | C3: =$H$3*(1+$H$1)*(A3^($H$1))*EXP(-$H$3*(A3^(1+$H$1))) -> 0.69300176 | D3: =B3-C3 -> 0.13847673 | E3: =D3^2 -> 0.019175804 | G3: a_b | H3: =(_xlfn.GAMMA((2+$H$1)/(1+$H$1)))^(1+$H$1) -> 0.92256368
A4: 0.4769988 | B4: 0.76257399 | C4: =$H$3*(1+$H$1)*(A4^($H$1))*EXP(-$H$3*(A4^(1+$H$1))) -> 0.6586845 | D4: =B4-C4 -> 0.10388948 | E4: =D4^2 -> 0.010793025
A5: 0.6129056 | B5: 0.628927 | C5: =$H$3*(1+$H$1)*(A5^($H$1))*EXP(-$H$3*(A5^(1+$H$1))) -> 0.60926473 | D5: =B5-C5 -> 0.019662265 | E5: =D5^2 -> 0.00038660465 | G5: SUM | H5: =SUM(E1:E40) -> 0.050445027
A6: 0.7488124 | B6: 0.48325641 | C6: =$H$3*(1+$H$1)*(A6^($H$1))*EXP(-$H$3*(A6^(1+$H$1))) -> 0.55346086 | D6: =B6-C6 -> -0.070204455 | E6: =D6^2 -> 0.0049286655
A7: 0.8847192 | B7: 0.44348602 | C7: =$H$3*(1+$H$1)*(A7^($H$1))*EXP(-$H$3*(A7^(1+$H$1))) -> 0.49612454 | D7: =B7-C7 -> -0.052638514 | E7: =D7^2 -> 0.0027708132
A8: 1.020626 | B8: 0.40417809 | C8: =$H$3*(1+$H$1)*(A8^($H$1))*EXP(-$H$3*(A8^(1+$H$1))) -> 0.44010739 | D8: =B8-C8 -> -0.035929302 | E8: =D8^2 -> 0.0012909148
A9: 1.1565328 | B9: 0.36487015 | C9: =$H$3*(1+$H$1)*(A9^($H$1))*EXP(-$H$3*(A9^(1+$H$1))) -> 0.38708443 | D9: =B9-C9 -> -0.022214284 | E9: =D9^2 -> 0.00049347444
A10: 1.2924396 | B10: 0.30613947 | C10: =$H$3*(1+$H$1)*(A10^($H$1))*EXP(-$H$3*(A10^(1+$H$1))) -> 0.33798901 | D10: =B10-C10 -> -0.031849545 | E10: =D10^2 -> 0.0010143935
A11: 1.4283464 | B11: 0.2705311 | C11: =$H$3*(1+$H$1)*(A11^($H$1))*EXP(-$H$3*(A11^(1+$H$1))) -> 0.29327074 | D11: =B11-C11 -> -0.022739639 | E11: =D11^2 -> 0.00051709119
A12: 1.5642532 | B12: 0.22706114 | C12: =$H$3*(1+$H$1)*(A12^($H$1))*EXP(-$H$3*(A12^(1+$H$1))) -> 0.25306038 | D12: =B12-C12 -> -0.025999238 | E12: =D12^2 -> 0.00067596037
A13: 1.70016 | B13: 0.20208904 | C13: =$H$3*(1+$H$1)*(A13^($H$1))*EXP(-$H$3*(A13^(1+$H$1))) -> 0.2172803 | D13: =B13-C13 -> -0.015191259 | E13: =D13^2 -> 0.00023077436
A14: 1.8360668 | B14: 0.1946899 | C14: =$H$3*(1+$H$1)*(A14^($H$1))*EXP(-$H$3*(A14^(1+$H$1))) -> 0.18572049 | D14: =B14-C14 -> 0.0089694111 | E14: =D14^2 -> 8.0450336e-05
A15: 1.9719736 | B15: 0.17249248 | C15: =$H$3*(1+$H$1)*(A15^($H$1))*EXP(-$H$3*(A15^(1+$H$1))) -> 0.15809164 | D15: =B15-C15 -> 0.014400837 | E15: =D15^2 -> 0.0002073841
A16: 2.1078804 | B16: 0.14012124 | C16: =$H$3*(1+$H$1)*(A16^($H$1))*EXP(-$H$3*(A16^(1+$H$1))) -> 0.13406228 | D16: =B16-C16 -> 0.0060589552 | E16: =D16^2 -> 3.6710938e-05
A17: 2.2437872 | B17: 0.12532295 | C17: =$H$3*(1+$H$1)*(A17^($H$1))*EXP(-$H$3*(A17^(1+$H$1))) -> 0.11328456 | D17: =B17-C17 -> 0.012038398 | E17: =D17^2 -> 0.00014492303
... A40: 5.3696437 | B40: 0.00046244632 | C40: =$H$3*(1+$H$1)*(A40^($H$1))*EXP(-$H$3*(A40^(1+$H$1))) -> 0.0012191104 | D40: =B40-C40 -> -0.00075666405 | E40: =D40^2 -> 5.7254048e-07

Sheet 0.05
A1: 0.067374713 | B1: 0.52752053 | C1: =$H$3*(1+$H$1)*(A1^($H$1))*EXP(-$H$3*(A1^(1+$H$1))) -> 0.53094623 | D1: =B1-C1 -> -0.0034256999 | E1: =D1^2 -> 1.173542e-05 | G1: b | H1: 0.27919095
A2: 0.19979088 | B2: 0.6039659 | C2: =$H$3*(1+$H$1)*(A2^($H$1))*EXP(-$H$3*(A2^(1+$H$1))) -> 0.6593895 | D2: =B2-C2 -> -0.055423601 | E2: =D2^2 -> 0.0030717756
A3: 0.33220705 | B3: 0.64290081 | C3: =$H$3*(1+$H$1)*(A3^($H$1))*EXP(-$H$3*(A3^(1+$H$1))) -> 0.6835739 | D3: =B3-C3 -> -0.040673095 | E3: =D3^2 -> 0.0016543007 | G3: a_b | H3: =(_xlfn.GAMMA((2+$H$1)/(1+$H$1)))^(1+$H$1) -> 0.9071682
A4: 0.46462322 | B4: 0.78819449 | C4: =$H$3*(1+$H$1)*(A4^($H$1))*EXP(-$H$3*(A4^(1+$H$1))) -> 0.66664663 | D4: =B4-C4 -> 0.12154786 | E4: =D4^2 -> 0.014773881
A5: 0.59703939 | B5: 0.76825222 | C5: =$H$3*(1+$H$1)*(A5^($H$1))*EXP(-$H$3*(A5^(1+$H$1))) -> 0.62865231 | D5: =B5-C5 -> 0.13959991 | E5: =D5^2 -> 0.019488135 | G5: SUM | H5: =SUM(E1:E40) -> 0.051870384
A6: 0.72945556 | B6: 0.58212436 | C6: =$H$3*(1+$H$1)*(A6^($H$1))*EXP(-$H$3*(A6^(1+$H$1))) -> 0.5797126 | D6: =B6-C6 -> 0.0024117655 | E6: =D6^2 -> 5.816613e-06
A7: 0.86187173 | B7: 0.46389519 | C7: =$H$3*(1+$H$1)*(A7^($H$1))*EXP(-$H$3*(A7^(1+$H$1))) -> 0.52582894 | D7: =B7-C7 -> -0.061933747 | E7: =D7^2 -> 0.003835789
A8: 0.9942879 | B8: 0.42068694 | C8: =$H$3*(1+$H$1)*(A8^($H$1))*EXP(-$H$3*(A8^(1+$H$1))) -> 0.47078966 | D8: =B8-C8 -> -0.050102723 | E8: =D8^2 -> 0.0025102828
A9: 1.1267041 | B9: 0.38839945 | C9: =$H$3*(1+$H$1)*(A9^($H$1))*EXP(-$H$3*(A9^(1+$H$1))) -> 0.41702072 | D9: =B9-C9 -> -0.028621264 | E9: =D9^2 -> 0.00081917678
A10: 1.2591202 | B10: 0.32619856 | C10: =$H$3*(1+$H$1)*(A10^($H$1))*EXP(-$H$3*(A10^(1+$H$1))) -> 0.36604531 | D10: =B10-C10 -> -0.039846743 | E10: =D10^2 -> 0.001587763
A11: 1.3915364 | B11: 0.27729252 | C11: =$H$3*(1+$H$1)*(A11^($H$1))*EXP(-$H$3*(A11^(1+$H$1))) -> 0.3187657 | D11: =B11-C11 -> -0.041473177 | E11: =D11^2 -> 0.0017200244
A12: 1.5239526 | B12: 0.24595467 | C12: =$H$3*(1+$H$1)*(A12^($H$1))*EXP(-$H$3*(A12^(1+$H$1))) -> 0.27565081 | D12: =B12-C12 -> -0.029696141 | E12: =D12^2 -> 0.0008818608
A13: 1.6563687 | B13: 0.21366718 | C13: =$H$3*(1+$H$1)*(A13^($H$1))*EXP(-$H$3*(A13^(1+$H$1))) -> 0.2368676 | D13: =B13-C13 -> -0.023200419 | E13: =D13^2 -> 0.00053825943
A14: 1.7887849 | B14: 0.20084715 | C14: =$H$3*(1+$H$1)*(A14^($H$1))*EXP(-$H$3*(A14^(1+$H$1))) -> 0.20237585 | D14: =B14-C14 -> -0.0015286998 | E14: =D14^2 -> 2.336923e-06
A15: 1.9212011 | B15: 0.16713522 | C15: =$H$3*(1+$H$1)*(A15^($H$1))*EXP(-$H$3*(A15^(1+$H$1))) -> 0.17199752 | D15: =B15-C15 -> -0.004862301 | E15: =D15^2 -> 2.3641971e-05
A16: 2.0536173 | B16: 0.15051666 | C16: =$H$3*(1+$H$1)*(A16^($H$1))*EXP(-$H$3*(A16^(1+$H$1))) -> 0.14546771 | D16: =B16-C16 -> 0.0050489515 | E16: =D16^2 -> 2.5491912e-05
A17: 2.1860334 | B17: 0.12630104 | C17: =$H$3*(1+$H$1)*(A17^($H$1))*EXP(-$H$3*(A17^(1+$H$1))) -> 0.12247192 | D17: =B17-C17 -> 0.0038291208 | E17: =D17^2 -> 1.4662166e-05
... A40: 5.2316053 | B40: 0.00047481596 | C40: =$H$3*(1+$H$1)*(A40^($H$1))*EXP(-$H$3*(A40^(1+$H$1))) -> 0.00098579249 | D40: =B40-C40 -> -0.00051097653 | E40: =D40^2 -> 2.6109702e-07

Sheet 0.075
A1: 0.065739674 | B1: 0.47126656 | C1: =$H$3*(1+$H$1)*(A1^($H$1))*EXP(-$H$3*(A1^(1+$H$1))) -> 0.47939814 | D1: =B1-C1 -> -0.0081315801 | E1: =D1^2 -> 6.6122596e-05 | G1: b | H1: 0.32379495
A2: 0.19496858 | B2: 0.64148668 | C2: =$H$3*(1+$H$1)*(A2^($H$1))*EXP(-$H$3*(A2^(1+$H$1))) -> 0.6302145 | D2: =B2-C2 -> 0.011272186 | E2: =D2^2 -> 0.00012706218
A3: 0.32419749 | B3: 0.58604356 | C3: =$H$3*(1+$H$1)*(A3^($H$1))*EXP(-$H$3*(A3^(1+$H$1))) -> 0.67311034 | D3: =B3-C3 -> -0.087066782 | E3: =D3^2 -> 0.0075806245 | G3: a_b | H3: =(_xlfn.GAMMA((2+$H$1)/(1+$H$1)))^(1+$H$1) -> 0.89588371
A4: 0.4534264 | B4: 0.67553071 | C4: =$H$3*(1+$H$1)*(A4^($H$1))*EXP(-$H$3*(A4^(1+$H$1))) -> 0.67033464 | D4: =B4-C4 -> 0.0051960675 | E4: =D4^2 -> 2.6999117e-05
A5: 0.58265531 | B5: 0.80343897 | C5: =$H$3*(1+$H$1)*(A5^($H$1))*EXP(-$H$3*(A5^(1+$H$1))) -> 0.64237967 | D5: =B5-C5 -> 0.1610593 | E5: =D5^2 -> 0.025940099 | G5: SUM | H5: =SUM(E1:E40) -> 0.054000563
A6: 0.71188421 | B6: 0.68866198 | C6: =$H$3*(1+$H$1)*(A6^($H$1))*EXP(-$H$3*(A6^(1+$H$1))) -> 0.60002098 | D6: =B6-C6 -> 0.088640996 | E6: =D6^2 -> 0.0078572262
A7: 0.84111312 | B7: 0.53157312 | C7: =$H$3*(1+$H$1)*(A7^($H$1))*EXP(-$H$3*(A7^(1+$H$1))) -> 0.54993748 | D7: =B7-C7 -> -0.018364361 | E7: =D7^2 -> 0.00033724975
A8: 0.97034203 | B8: 0.44062694 | C8: =$H$3*(1+$H$1)*(A8^($H$1))*EXP(-$H$3*(A8^(1+$H$1))) -> 0.49655012 | D8: =B8-C8 -> -0.055923177 | E8: =D8^2 -> 0.0031274018
A9: 1.0995709 | B9: 0.40950098 | C9: =$H$3*(1+$H$1)*(A9^($H$1))*EXP(-$H$3*(A9^(1+$H$1))) -> 0.44284231 | D9: =B9-C9 -> -0.033341338 | E9: =D9^2 -> 0.0011116448
A10: 1.2287998 | B10: 0.35162614 | C10: =$H$3*(1+$H$1)*(A10^($H$1))*EXP(-$H$3*(A10^(1+$H$1))) -> 0.39080835 | D10: =B10-C10 -> -0.039182218 | E10: =D10^2 -> 0.0015352462
A11: 1.3580288 | B11: 0.30493719 | C11: =$H$3*(1+$H$1)*(A11^($H$1))*EXP(-$H$3*(A11^(1+$H$1))) -> 0.34173476 | D11: =B11-C11 -> -0.036797568 | E11: =D11^2 -> 0.001354061
A12: 1.4872577 | B12: 0.24268526 | C12: =$H$3*(1+$H$1)*(A12^($H$1))*EXP(-$H$3*(A12^(1+$H$1))) -> 0.29639362 | D12: =B12-C12 -> -0.053708359 | E12: =D12^2 -> 0.0028845879
A13: 1.6164866 | B13: 0.22079981 | C13: =$H$3*(1+$H$1)*(A13^($H$1))*EXP(-$H$3*(A13^(1+$H$1))) -> 0.25518303 | D13: =B13-C13 -> -0.034383219 | E13: =D13^2 -> 0.0011822057
A14: 1.7457155 | B14: 0.21447735 | C14: =$H$3*(1+$H$1)*(A14^($H$1))*EXP(-$H$3*(A14^(1+$H$1))) -> 0.21823232 | D14: =B14-C14 -> -0.0037549689 | E14: =D14^2 -> 1.4099792e-05
A15: 1.8749444 | B15: 0.18043333 | C15: =$H$3*(1+$H$1)*(A15^($H$1))*EXP(-$H$3*(A15^(1+$H$1))) -> 0.18548202 | D15: =B15-C15 -> -0.0050486898 | E15: =D15^2 -> 2.5489268e-05
A16: 2.0041733 | B16: 0.1463893 | C16: =$H$3*(1+$H$1)*(A16^($H$1))*EXP(-$H$3*(A16^(1+$H$1))) -> 0.15674488 | D16: =B16-C16 -> -0.010355575 | E16: =D16^2 -> 0.00010723794
A17: 2.1334022 | B17: 0.13520341 | C17: =$H$3*(1+$H$1)*(A17^($H$1))*EXP(-$H$3*(A17^(1+$H$1))) -> 0.13175219 | D17: =B17-C17 -> 0.0034512209 | E17: =D17^2 -> 1.1910925e-05
... A40: 5.1056671 | B40: 0.0004863432 | C40: =$H$3*(1+$H$1)*(A40^($H$1))*EXP(-$H$3*(A40^(1+$H$1))) -> 0.00086196544 | D40: =B40-C40 -> -0.00037562224 | E40: =D40^2 -> 1.4109206e-07

Sheet 0.1
A1: 0.065216376 | B1: 0.41374307 | C1: =$H$3*(1+$H$1)*(A1^($H$1))*EXP(-$H$3*(A1^(1+$H$1))) -> 0.43868983 | D1: =B1-C1 -> -0.02494676 | E1: =D1^2 -> 0.00062234085 | G1: b | H1: 0.36335414
A2: 0.19144935 | B2: 0.65471977 | C2: =$H$3*(1+$H$1)*(A2^($H$1))*EXP(-$H$3*(A2^(1+$H$1))) -> 0.6039271 | D2: =B2-C2 -> 0.050792675 | E2: =D2^2 -> 0.0025798959
A3: 0.31768233 | B3: 0.60343754 | C3: =$H$3*(1+$H$1)*(A3^($H$1))*EXP(-$H$3*(A3^(1+$H$1))) -> 0.66175144 | D3: =B3-C3 -> -0.058313899 | E3: =D3^2 -> 0.0034005108 | G3: a_b | H3: =(_xlfn.GAMMA((2+$H$1)/(1+$H$1)))^(1+$H$1) -> 0.88647889
A4: 0.4439153 | B4: 0.62534451 | C4: =$H$3*(1+$H$1)*(A4^($H$1))*EXP(-$H$3*(A4^(1+$H$1))) -> 0.67125831 | D4: =B4-C4 -> -0.045913793 | E4: =D4^2 -> 0.0021080764
A5: 0.57014828 | B5: 0.7308963 | C5: =$H$3*(1+$H$1)*(A5^($H$1))*EXP(-$H$3*(A5^(1+$H$1))) -> 0.65259733 | D5: =B5-C5 -> 0.078298967 | E5: =D5^2 -> 0.0061307282 | G5: SUM | H5: =SUM(E1:E40) -> 0.044213823
A6: 0.69638125 | B6: 0.73985824 | C6: =$H$3*(1+$H$1)*(A6^($H$1))*EXP(-$H$3*(A6^(1+$H$1))) -> 0.61674366 | D6: =B6-C6 -> 0.12311458 | E6: =D6^2 -> 0.0151572
A7: 0.82261423 | B7: 0.61638257 | C7: =$H$3*(1+$H$1)*(A7^($H$1))*EXP(-$H$3*(A7^(1+$H$1))) -> 0.57076111 | D7: =B7-C7 -> 0.045621464 | E7: =D7^2 -> 0.002081318
A8: 0.9488472 | B8: 0.49091536 | C8: =$H$3*(1+$H$1)*(A8^($H$1))*EXP(-$H$3*(A8^(1+$H$1))) -> 0.51951159 | D8: =B8-C8 -> -0.028596234 | E8: =D8^2 -> 0.0008177446
A9: 1.0750802 | B9: 0.44162467 | C9: =$H$3*(1+$H$1)*(A9^($H$1))*EXP(-$H$3*(A9^(1+$H$1))) -> 0.46641329 | D9: =B9-C9 -> -0.024788619 | E9: =D9^2 -> 0.00061447565
A10: 1.2013132 | B10: 0.36096718 | C10: =$H$3*(1+$H$1)*(A10^($H$1))*EXP(-$H$3*(A10^(1+$H$1))) -> 0.41385691 | D10: =B10-C10 -> -0.052889734 | E10: =D10^2 -> 0.0027973239
A11: 1.3275461 | B11: 0.32760883 | C11: =$H$3*(1+$H$1)*(A11^($H$1))*EXP(-$H$3*(A11^(1+$H$1))) -> 0.36347179 | D11: =B11-C11 -> -0.035862955 | E11: =D11^2 -> 0.0012861516
A12: 1.4537791 | B12: 0.25790482 | C12: =$H$3*(1+$H$1)*(A12^($H$1))*EXP(-$H$3*(A12^(1+$H$1))) -> 0.31631404 | D12: =B12-C12 -> -0.058409213 | E12: =D12^2 -> 0.0034116362
A13: 1.5800121 | B13: 0.23052111 | C13: =$H$3*(1+$H$1)*(A13^($H$1))*EXP(-$H$3*(A13^(1+$H$1))) -> 0.27300808 | D13: =B13-C13 -> -0.042486971 | E13: =D13^2 -> 0.0018051427
A14: 1.7062451 | B14: 0.21259722 | C14: =$H$3*(1+$H$1)*(A14^($H$1))*EXP(-$H$3*(A14^(1+$H$1))) -> 0.23385656 | D14: =B14-C14 -> -0.021259341 | E14: =D14^2 -> 0.00045195959
A15: 1.832478 | B15: 0.19019236 | C15: =$H$3*(1+$H$1)*(A15^($H$1))*EXP(-$H$3*(A15^(1+$H$1))) -> 0.198927 | D15: =B15-C15 -> -0.008734636 | E15: =D15^2 -> 7.6293866e-05
A16: 1.958711 | B16: 0.15583824 | C16: =$H$3*(1+$H$1)*(A16^($H$1))*EXP(-$H$3*(A16^(1+$H$1))) -> 0.16812014 | D16: =B16-C16 -> -0.012281897 | E16: =D16^2 -> 0.00015084498
A17: 2.084944 | B17: 0.13741647 | C17: =$H$3*(1+$H$1)*(A17^($H$1))*EXP(-$H$3*(A17^(1+$H$1))) -> 0.14122364 | D17: =B17-C17 -> -0.0038071669 | E17: =D17^2 -> 1.449452e-05
... A40: 4.9883024 | B40: 0.00049788576 | C40: =$H$3*(1+$H$1)*(A40^($H$1))*EXP(-$H$3*(A40^(1+$H$1))) -> 0.00078038043 | D40: =B40-C40 -> -0.00028249467 | E40: =D40^2 -> 7.980324e-08

Sheet 0.15
A1: 0.062892483 | B1: 0.34354622 | C1: =$H$3*(1+$H$1)*(A1^($H$1))*EXP(-$H$3*(A1^(1+$H$1))) -> 0.37365703 | D1: =B1-C1 -> -0.030110802 | E1: =D1^2 -> 0.00090666038 | G1: b | H1: 0.42941047
A2: 0.18364288 | B2: 0.61473953 | C2: =$H$3*(1+$H$1)*(A2^($H$1))*EXP(-$H$3*(A2^(1+$H$1))) -> 0.55716461 | D2: =B2-C2 -> 0.057574918 | E2: =D2^2 -> 0.0033148711
A3: 0.30439328 | B3: 0.63920419 | C3: =$H$3*(1+$H$1)*(A3^($H$1))*EXP(-$H$3*(A3^(1+$H$1))) -> 0.63774453 | D3: =B3-C3 -> 0.0014596589 | E3: =D3^2 -> 2.130604e-06 | G3: a_b | H3: =(_xlfn.GAMMA((2+$H$1)/(1+$H$1)))^(1+$H$1) -> 0.87190839
A4: 0.42514368 | B4: 0.61369848 | C4: =$H$3*(1+$H$1)*(A4^($H$1))*EXP(-$H$3*(A4^(1+$H$1))) -> 0.66775291 | D4: =B4-C4 -> -0.054054426 | E4: =D4^2 -> 0.0029218809
A5: 0.54589408 | B5: 0.62775264 | C5: =$H$3*(1+$H$1)*(A5^($H$1))*EXP(-$H$3*(A5^(1+$H$1))) -> 0.66580069 | D5: =B5-C5 -> -0.038048044 | E5: =D5^2 -> 0.0014476536 | G5: SUM | H5: =SUM(E1:E40) -> 0.039659215
A6: 0.66664448 | B6: 0.68292825 | C6: =$H$3*(1+$H$1)*(A6^($H$1))*EXP(-$H$3*(A6^(1+$H$1))) -> 0.64255818 | D6: =B6-C6 -> 0.040370074 | E6: =D6^2 -> 0.0016297428
A7: 0.78739488 | B7: 0.71728287 | C7: =$H$3*(1+$H$1)*(A7^($H$1))*EXP(-$H$3*(A7^(1+$H$1))) -> 0.60530994 | D7: =B7-C7 -> 0.11197293 | E7: =D7^2 -> 0.012537937
A8: 0.90814528 | B8: 0.61734215 | C8: =$H$3*(1+$H$1)*(A8^($H$1))*EXP(-$H$3*(A8^(1+$H$1))) -> 0.55938906 | D8: =B8-C8 -> 0.057953096 | E8: =D8^2 -> 0.0033585613
A9: 1.0288957 | B9: 0.52364773 | C9: =$H$3*(1+$H$1)*(A9^($H$1))*EXP(-$H$3*(A9^(1+$H$1))) -> 0.5087898 | D9: =B9-C9 -> 0.014857933 | E9: =D9^2 -> 0.00022075816
A10: 1.1496461 | B10: 0.42683016 | C10: =$H$3*(1+$H$1)*(A10^($H$1))*EXP(-$H$3*(A10^(1+$H$1))) -> 0.45649777 | D10: =B10-C10 -> -0.029667618 | E10: =D10^2 -> 0.00088016759
A11: 1.2703965 | B11: 0.35031304 | C11: =$H$3*(1+$H$1)*(A11^($H$1))*EXP(-$H$3*(A11^(1+$H$1))) -> 0.40470434 | D11: =B11-C11 -> -0.0543913 | E11: =D11^2 -> 0.0029584136
A12: 1.3911469 | B12: 0.3112737 | C12: =$H$3*(1+$H$1)*(A12^($H$1))*EXP(-$H$3*(A12^(1+$H$1))) -> 0.35496557 | D12: =B12-C12 -> -0.043691874 | E12: =D12^2 -> 0.0019089799
A13: 1.5118973 | B13: 0.23944131 | C13: =$H$3*(1+$H$1)*(A13^($H$1))*EXP(-$H$3*(A13^(1+$H$1))) -> 0.30832986 | D13: =B13-C13 -> -0.068888551 | E13: =D13^2 -> 0.0047456325
A14: 1.6326477 | B14: 0.2436055 | C14: =$H$3*(1+$H$1)*(A14^($H$1))*EXP(-$H$3*(A14^(1+$H$1))) -> 0.2654443 | D14: =B14-C14 -> -0.021838793 | E14: =D14^2 -> 0.00047693289
A15: 1.7533981 | B15: 0.19259409 | C15: =$H$3*(1+$H$1)*(A15^($H$1))*EXP(-$H$3*(A15^(1+$H$1))) -> 0.22664451 | D15: =B15-C15 -> -0.034050414 | E15: =D15^2 -> 0.0011594307
A16: 1.8741485 | B16: 0.17385521 | C16: =$H$3*(1+$H$1)*(A16^($H$1))*EXP(-$H$3*(A16^(1+$H$1))) -> 0.19203029 | D16: =B16-C16 -> -0.018175081 | E16: =D16^2 -> 0.00033033356
A17: 1.9948989 | B17: 0.15199318 | C17: =$H$3*(1+$H$1)*(A17^($H$1))*EXP(-$H$3*(A17^(1+$H$1))) -> 0.16152869 | D17: =B17-C17 -> -0.0095355103 | E17: =D17^2 -> 9.0925956e-05
... A40: 4.7721581 | B40: 0.00052052458 | C40: =$H$3*(1+$H$1)*(A40^($H$1))*EXP(-$H$3*(A40^(1+$H$1))) -> 0.00071096562 | D40: =B40-C40 -> -0.00019044104 | E40: =D40^2 -> 3.626779e-08

Sheet 0.2
A1: 0.06227026 | B1: 0.28687846 | C1: =$H$3*(1+$H$1)*(A1^($H$1))*EXP(-$H$3*(A1^(1+$H$1))) -> 0.32403544 | D1: =B1-C1 -> -0.037156983 | E1: =D1^2 -> 0.0013806414 | G1: b | H1: 0.49015118
A2: 0.17793772 | B2: 0.56017366 | C2: =$H$3*(1+$H$1)*(A2^($H$1))*EXP(-$H$3*(A2^(1+$H$1))) -> 0.51470094 | D2: =B2-C2 -> 0.045472722 | E2: =D2^2 -> 0.0020677685
A3: 0.29360519 | B3: 0.63786991 | C3: =$H$3*(1+$H$1)*(A3^($H$1))*EXP(-$H$3*(A3^(1+$H$1))) -> 0.61171381 | D3: =B3-C3 -> 0.0261561 | E3: =D3^2 -> 0.00068414158 | G3: a_b | H3: =(_xlfn.GAMMA((2+$H$1)/(1+$H$1)))^(1+$H$1) -> 0.85962472
A4: 0.40927265 | B4: 0.65090984 | C4: =$H$3*(1+$H$1)*(A4^($H$1))*EXP(-$H$3*(A4^(1+$H$1))) -> 0.65880055 | D4: =B4-C4 -> -0.0078907117 | E4: =D4^2 -> 6.2263332e-05
A5: 0.52494011 | B5: 0.64330322 | C5: =$H$3*(1+$H$1)*(A5^($H$1))*EXP(-$H$3*(A5^(1+$H$1))) -> 0.67213506 | D5: =B5-C5 -> -0.028831844 | E5: =D5^2 -> 0.00083127524 | G5: SUM | H5: =SUM(E1:E40) -> 0.032292405
A6: 0.64060757 | B6: 0.62808996 | C6: =$H$3*(1+$H$1)*(A6^($H$1))*EXP(-$H$3*(A6^(1+$H$1))) -> 0.66142611 | D6: =B6-C6 -> -0.033336146 | E6: =D6^2 -> 0.0011112986
A7: 0.75627504 | B7: 0.64112989 | C7: =$H$3*(1+$H$1)*(A7^($H$1))*EXP(-$H$3*(A7^(1+$H$1))) -> 0.63366952 | D7: =B7-C7 -> 0.0074603702 | E7: =D7^2 -> 5.5657123e-05
A8: 0.8719425 | B8: 0.69709293 | C8: =$H$3*(1+$H$1)*(A8^($H$1))*EXP(-$H$3*(A8^(1+$H$1))) -> 0.59428229 | D8: =B8-C8 -> 0.10281064 | E8: =D8^2 -> 0.010570028
A9: 0.98760996 | B9: 0.61016006 | C9: =$H$3*(1+$H$1)*(A9^($H$1))*EXP(-$H$3*(A9^(1+$H$1))) -> 0.54755386 | D9: =B9-C9 -> 0.0626062 | E9: =D9^2 -> 0.0039195362
A10: 1.1032774 | B10: 0.51073059 | C10: =$H$3*(1+$H$1)*(A10^($H$1))*EXP(-$H$3*(A10^(1+$H$1))) -> 0.49687383 | D10: =B10-C10 -> 0.013856765 | E10: =D10^2 -> 0.00019200992
A11: 1.2189449 | B11: 0.4286877 | C11: =$H$3*(1+$H$1)*(A11^($H$1))*EXP(-$H$3*(A11^(1+$H$1))) -> 0.44487744 | D11: =B11-C11 -> -0.01618974 | E11: =D11^2 -> 0.00026210767
A12: 1.3346124 | B12: 0.34066817 | C12: =$H$3*(1+$H$1)*(A12^($H$1))*EXP(-$H$3*(A12^(1+$H$1))) -> 0.39355858 | D12: =B12-C12 -> -0.052890412 | E12: =D12^2 -> 0.0027973957
A13: 1.4502798 | B13: 0.29557175 | C13: =$H$3*(1+$H$1)*(A13^($H$1))*EXP(-$H$3*(A13^(1+$H$1))) -> 0.34436816 | D13: =B13-C13 -> -0.048796409 | E13: =D13^2 -> 0.0023810896
A14: 1.5659473 | B14: 0.25101865 | C14: =$H$3*(1+$H$1)*(A14^($H$1))*EXP(-$H$3*(A14^(1+$H$1))) -> 0.29830374 | D14: =B14-C14 -> -0.047285084 | E14: =D14^2 -> 0.0022358792
A15: 1.6816147 | B15: 0.21244219 | C15: =$H$3*(1+$H$1)*(A15^($H$1))*EXP(-$H$3*(A15^(1+$H$1))) -> 0.25599196 | D15: =B15-C15 -> -0.043549767 | E15: =D15^2 -> 0.0018965822
A16: 1.7972822 | B16: 0.19994559 | C16: =$H$3*(1+$H$1)*(A16^($H$1))*EXP(-$H$3*(A16^(1+$H$1))) -> 0.21776329 | D16: =B16-C16 -> -0.017817699 | E16: =D16^2 -> 0.0003174704
A17: 1.9129497 | B17: 0.15810915 | C17: =$H$3*(1+$H$1)*(A17^($H$1))*EXP(-$H$3*(A17^(1+$H$1))) -> 0.18371864 | D17: =B17-C17 -> -0.025609491 | E17: =D17^2 -> 0.00065584605
... A40: 4.5733013 | B40: 0.00054333042 | C40: =$H$3*(1+$H$1)*(A40^($H$1))*EXP(-$H$3*(A40^(1+$H$1))) -> 0.00068264199 | D40: =B40-C40 -> -0.00013931157 | E40: =D40^2 -> 1.9407713e-08

Sheet 0.25
A1: 0.064744788 | B1: 0.26771608 | C1: =$H$3*(1+$H$1)*(A1^($H$1))*EXP(-$H$3*(A1^(1+$H$1))) -> 0.28835911 | D1: =B1-C1 -> -0.020643026 | E1: =D1^2 -> 0.00042613453 | G1: b | H1: 0.5498873
A2: 0.17554556 | B2: 0.4730407 | C2: =$H$3*(1+$H$1)*(A2^($H$1))*EXP(-$H$3*(A2^(1+$H$1))) -> 0.47707142 | D2: =B2-C2 -> -0.0040307227 | E2: =D2^2 -> 1.6246726e-05
A3: 0.28634633 | B3: 0.62731776 | C3: =$H$3*(1+$H$1)*(A3^($H$1))*EXP(-$H$3*(A3^(1+$H$1))) -> 0.58510979 | D3: =B3-C3 -> 0.042207968 | E3: =D3^2 -> 0.0017815126 | G3: a_b | H3: =(_xlfn.GAMMA((2+$H$1)/(1+$H$1)))^(1+$H$1) -> 0.84846232
A4: 0.39714709 | B4: 0.68687325 | C4: =$H$3*(1+$H$1)*(A4^($H$1))*EXP(-$H$3*(A4^(1+$H$1))) -> 0.64614408 | D4: =B4-C4 -> 0.040729162 | E4: =D4^2 -> 0.0016588646
A5: 0.50794786 | B5: 0.64943837 | C5: =$H$3*(1+$H$1)*(A5^($H$1))*EXP(-$H$3*(A5^(1+$H$1))) -> 0.67328975 | D5: =B5-C5 -> -0.023851383 | E5: =D5^2 -> 0.00056888846 | G5: SUM | H5: =SUM(E1:E40) -> 0.030445973
A6: 0.61874863 | B6: 0.64943837 | C6: =$H$3*(1+$H$1)*(A6^($H$1))*EXP(-$H$3*(A6^(1+$H$1))) -> 0.67482084 | D6: =B6-C6 -> -0.025382469 | E6: =D6^2 -> 0.00064426971
A7: 0.7295494 | B7: 0.63922886 | C7: =$H$3*(1+$H$1)*(A7^($H$1))*EXP(-$H$3*(A7^(1+$H$1))) -> 0.65704887 | D7: =B7-C7 -> -0.017820013 | E7: =D7^2 -> 0.00031755286
A8: 0.84035017 | B8: 0.62618337 | C8: =$H$3*(1+$H$1)*(A8^($H$1))*EXP(-$H$3*(A8^(1+$H$1))) -> 0.62515081 | D8: =B8-C8 -> 0.0010325596 | E8: =D8^2 -> 1.0661793e-06
A9: 0.95115094 | B9: 0.68290288 | C9: =$H$3*(1+$H$1)*(A9^($H$1))*EXP(-$H$3*(A9^(1+$H$1))) -> 0.583459 | D9: =B9-C9 -> 0.099443882 | E9: =D9^2 -> 0.0098890856
A10: 1.0619517 | B10: 0.59782362 | C10: =$H$3*(1+$H$1)*(A10^($H$1))*EXP(-$H$3*(A10^(1+$H$1))) -> 0.53558286 | D10: =B10-C10 -> 0.062240758 | E10: =D10^2 -> 0.003873912
A11: 1.1727525 | B11: 0.48381741 | C11: =$H$3*(1+$H$1)*(A11^($H$1))*EXP(-$H$3*(A11^(1+$H$1))) -> 0.48447816 | D11: =B11-C11 -> -0.00066075194 | E11: =D11^2 -> 4.3659313e-07
A12: 1.2835532 | B12: 0.41235083 | C12: =$H$3*(1+$H$1)*(A12^($H$1))*EXP(-$H$3*(A12^(1+$H$1))) -> 0.43250396 | D12: =B12-C12 -> -0.020153136 | E12: =D12^2 -> 0.00040614888
A13: 1.394354 | B13: 0.32443559 | C13: =$H$3*(1+$H$1)*(A13^($H$1))*EXP(-$H$3*(A13^(1+$H$1))) -> 0.38148076 | D13: =B13-C13 -> -0.057045172 | E13: =D13^2 -> 0.0032541516
A14: 1.5051548 | B14: 0.29721022 | C14: =$H$3*(1+$H$1)*(A14^($H$1))*EXP(-$H$3*(A14^(1+$H$1))) -> 0.33275273 | D14: =B14-C14 -> -0.035542508 | E14: =D14^2 -> 0.0012632699
A15: 1.6159555 | B15: 0.23708754 | C15: =$H$3*(1+$H$1)*(A15^($H$1))*EXP(-$H$3*(A15^(1+$H$1))) -> 0.28725307 | D15: =B15-C15 -> -0.050165523 | E15: =D15^2 -> 0.0025165797
A16: 1.7267563 | B16: 0.20192145 | C16: =$H$3*(1+$H$1)*(A16^($H$1))*EXP(-$H$3*(A16^(1+$H$1))) -> 0.24556989 | D16: =B16-C16 -> -0.043648437 | E16: =D16^2 -> 0.0019051861
A17: 1.8375571 | B17: 0.18603999 | C17: =$H$3*(1+$H$1)*(A17^($H$1))*EXP(-$H$3*(A17^(1+$H$1))) -> 0.20801013 | D17: =B17-C17 -> -0.021970146 | E17: =D17^2 -> 0.00048268732
... A40: 4.3859748 | B40: 0.00056719508 | C40: =$H$3*(1+$H$1)*(A40^($H$1))*EXP(-$H$3*(A40^(1+$H$1))) -> 0.00067337939 | D40: =B40-C40 -> -0.0001061843 | E40: =D40^2 -> 1.1275106e-08

Sheet 0.3
A1: 0.06074564 | B1: 0.20160654 | C1: =$H$3*(1+$H$1)*(A1^($H$1))*EXP(-$H$3*(A1^(1+$H$1))) -> 0.23999154 | D1: =B1-C1 -> -0.038385002 | E1: =D1^2 -> 0.0014734084 | G1: b | H1: 0.61375793
A2: 0.16704362 | B2: 0.43573026 | C2: =$H$3*(1+$H$1)*(A2^($H$1))*EXP(-$H$3*(A2^(1+$H$1))) -> 0.43006258 | D2: =B2-C2 -> 0.0056676777 | E2: =D2^2 -> 3.2122571e-05
A3: 0.27334159 | B3: 0.565799 | C3: =$H$3*(1+$H$1)*(A3^($H$1))*EXP(-$H$3*(A3^(1+$H$1))) -> 0.54980891 | D3: =B3-C3 -> 0.015990085 | E3: =D3^2 -> 0.00025568282 | G3: a_b | H3: =(_xlfn.GAMMA((2+$H$1)/(1+$H$1)))^(1+$H$1) -> 0.83742143
A4: 0.37963957 | B4: 0.68581696 | C4: =$H$3*(1+$H$1)*(A4^($H$1))*EXP(-$H$3*(A4^(1+$H$1))) -> 0.62578008 | D4: =B4-C4 -> 0.060036884 | E4: =D4^2 -> 0.0036044275
A5: 0.48593754 | B5: 0.68699941 | C5: =$H$3*(1+$H$1)*(A5^($H$1))*EXP(-$H$3*(A5^(1+$H$1))) -> 0.66823927 | D5: =B5-C5 -> 0.018760142 | E5: =D5^2 -> 0.00035194291 | G5: SUM | H5: =SUM(E1:E40) -> 0.02608297
A6: 0.59223552 | B6: 0.6621681 | C6: =$H$3*(1+$H$1)*(A6^($H$1))*EXP(-$H$3*(A6^(1+$H$1))) -> 0.68388337 | D6: =B6-C6 -> -0.021715263 | E6: =D6^2 -> 0.00047155263
A7: 0.6985335 | B7: 0.67399253 | C7: =$H$3*(1+$H$1)*(A7^($H$1))*EXP(-$H$3*(A7^(1+$H$1))) -> 0.67813091 | D7: =B7-C7 -> -0.0041383727 | E7: =D7^2 -> 1.7126128e-05
A8: 0.80483147 | B8: 0.62669481 | C8: =$H$3*(1+$H$1)*(A8^($H$1))*EXP(-$H$3*(A8^(1+$H$1))) -> 0.65572237 | D8: =B8-C8 -> -0.029027554 | E8: =D8^2 -> 0.00084259888
A9: 0.91112945 | B9: 0.62728603 | C9: =$H$3*(1+$H$1)*(A9^($H$1))*EXP(-$H$3*(A9^(1+$H$1))) -> 0.6208777 | D9: =B9-C9 -> 0.0064083309 | E9: =D9^2 -> 4.1066705e-05
A10: 1.0174274 | B10: 0.65152612 | C10: =$H$3*(1+$H$1)*(A10^($H$1))*EXP(-$H$3*(A10^(1+$H$1))) -> 0.57732113 | D10: =B10-C10 -> 0.074204989 | E10: =D10^2 -> 0.0055063804
A11: 1.1237254 | B11: 0.58826541 | C11: =$H$3*(1+$H$1)*(A11^($H$1))*EXP(-$H$3*(A11^(1+$H$1))) -> 0.52827276 | D11: =B11-C11 -> 0.059992658 | E11: =D11^2 -> 0.003599119
A12: 1.2300234 | B12: 0.47356844 | C12: =$H$3*(1+$H$1)*(A12^($H$1))*EXP(-$H$3*(A12^(1+$H$1))) -> 0.47644271 | D12: =B12-C12 -> -0.0028742749 | E12: =D12^2 -> 8.2614564e-06
A13: 1.3363214 | B13: 0.38311155 | C13: =$H$3*(1+$H$1)*(A13^($H$1))*EXP(-$H$3*(A13^(1+$H$1))) -> 0.42403955 | D13: =B13-C13 -> -0.040928001 | E13: =D13^2 -> 0.0016751012
A14: 1.4426193 | B14: 0.33817871 | C14: =$H$3*(1+$H$1)*(A14^($H$1))*EXP(-$H$3*(A14^(1+$H$1))) -> 0.37279498 | D14: =B14-C14 -> -0.034616271 | E14: =D14^2 -> 0.0011982862
A15: 1.5489173 | B15: 0.28496877 | C15: =$H$3*(1+$H$1)*(A15^($H$1))*EXP(-$H$3*(A15^(1+$H$1))) -> 0.3240028 | D15: =B15-C15 -> -0.039034026 | E15: =D15^2 -> 0.0015236552
A16: 1.6552153 | B16: 0.24062716 | C16: =$H$3*(1+$H$1)*(A16^($H$1))*EXP(-$H$3*(A16^(1+$H$1))) -> 0.27856792 | D16: =B16-C16 -> -0.037940762 | E16: =D16^2 -> 0.0014395014
A17: 1.7615133 | B17: 0.18623478 | C17: =$H$3*(1+$H$1)*(A17^($H$1))*EXP(-$H$3*(A17^(1+$H$1))) -> 0.23706145 | D17: =B17-C17 -> -0.050826674 | E17: =D17^2 -> 0.0025833508
... A40: 4.2063667 | B40: 0.00059122152 | C40: =$H$3*(1+$H$1)*(A40^($H$1))*EXP(-$H$3*(A40^(1+$H$1))) -> 0.00065939273 | D40: =B40-C40 -> -6.8171208e-05 | E40: =D40^2 -> 4.6473137e-09

Sheet 0.35
A1: 0.064410688 | B1: 0.16492508 | C1: =$H$3*(1+$H$1)*(A1^($H$1))*EXP(-$H$3*(A1^(1+$H$1))) -> 0.21653093 | D1: =B1-C1 -> -0.05160585 | E1: =D1^2 -> 0.0026631638 | G1: b | H1: 0.6737332
A2: 0.16614618 | B2: 0.39594374 | C2: =$H$3*(1+$H$1)*(A2^($H$1))*EXP(-$H$3*(A2^(1+$H$1))) -> 0.39683301 | D2: =B2-C2 -> -0.00088927126 | E2: =D2^2 -> 7.9080337e-07
A3: 0.26788167 | B3: 0.54295561 | C3: =$H$3*(1+$H$1)*(A3^($H$1))*EXP(-$H$3*(A3^(1+$H$1))) -> 0.52065536 | D3: =B3-C3 -> 0.02230025 | E3: =D3^2 -> 0.00049730117 | G3: a_b | H3: =(_xlfn.GAMMA((2+$H$1)/(1+$H$1)))^(1+$H$1) -> 0.82780439
A4: 0.36961716 | B4: 0.65970033 | C4: =$H$3*(1+$H$1)*(A4^($H$1))*EXP(-$H$3*(A4^(1+$H$1))) -> 0.60594836 | D4: =B4-C4 -> 0.053751968 | E4: =D4^2 -> 0.0028892741
A5: 0.47135265 | B5: 0.68440821 | C5: =$H$3*(1+$H$1)*(A5^($H$1))*EXP(-$H$3*(A5^(1+$H$1))) -> 0.65985264 | D5: =B5-C5 -> 0.024555564 | E5: =D5^2 -> 0.00060297572 | G5: SUM | H5: =SUM(E1:E40) -> 0.025253263
A6: 0.57308815 | B6: 0.71776384 | C6: =$H$3*(1+$H$1)*(A6^($H$1))*EXP(-$H$3*(A6^(1+$H$1))) -> 0.68727025 | D6: =B6-C6 -> 0.030493596 | E6: =D6^2 -> 0.00092985938
A7: 0.67482364 | B7: 0.68996748 | C7: =$H$3*(1+$H$1)*(A7^($H$1))*EXP(-$H$3*(A7^(1+$H$1))) -> 0.69247055 | D7: =B7-C7 -> -0.0025030694 | E7: =D7^2 -> 6.2653565e-06
A8: 0.77655913 | B8: 0.64302251 | C8: =$H$3*(1+$H$1)*(A8^($H$1))*EXP(-$H$3*(A8^(1+$H$1))) -> 0.67947535 | D8: =B8-C8 -> -0.036452837 | E8: =D8^2 -> 0.0013288093
A9: 0.87829462 | B9: 0.63437476 | C9: =$H$3*(1+$H$1)*(A9^($H$1))*EXP(-$H$3*(A9^(1+$H$1))) -> 0.65211012 | D9: =B9-C9 -> -0.017735359 | E9: =D9^2 -> 0.00031454297
A10: 0.98003011 | B10: 0.62881548 | C10: =$H$3*(1+$H$1)*(A10^($H$1))*EXP(-$H$3*(A10^(1+$H$1))) -> 0.61395446 | D10: =B10-C10 -> 0.014861027 | E10: =D10^2 -> 0.00022085012
A11: 1.0817656 | B11: 0.62696239 | C11: =$H$3*(1+$H$1)*(A11^($H$1))*EXP(-$H$3*(A11^(1+$H$1))) -> 0.56827146 | D11: =B11-C11 -> 0.05869093 | E11: =D11^2 -> 0.0034446252
A12: 1.1835011 | B12: 0.56766349 | C12: =$H$3*(1+$H$1)*(A12^($H$1))*EXP(-$H$3*(A12^(1+$H$1))) -> 0.5179467 | D12: =B12-C12 -> 0.049716789 | E12: =D12^2 -> 0.0024717591
A13: 1.2852366 | B13: 0.46080192 | C13: =$H$3*(1+$H$1)*(A13^($H$1))*EXP(-$H$3*(A13^(1+$H$1))) -> 0.4654484 | D13: =B13-C13 -> -0.0046464847 | E13: =D13^2 -> 2.158982e-05
A14: 1.3869721 | B14: 0.36814738 | C14: =$H$3*(1+$H$1)*(A14^($H$1))*EXP(-$H$3*(A14^(1+$H$1))) -> 0.4128116 | D14: =B14-C14 -> -0.044664227 | E14: =D14^2 -> 0.0019948932
A15: 1.4887076 | B15: 0.33355635 | C15: =$H$3*(1+$H$1)*(A15^($H$1))*EXP(-$H$3*(A15^(1+$H$1))) -> 0.36164444 | D15: =B15-C15 -> -0.02808809 | E15: =D15^2 -> 0.00078894079
A16: 1.5904431 | B16: 0.26560968 | C16: =$H$3*(1+$H$1)*(A16^($H$1))*EXP(-$H$3*(A16^(1+$H$1))) -> 0.3131528 | D16: =B16-C16 -> -0.047543114 | E16: =D16^2 -> 0.0022603477
A17: 1.6921786 | B17: 0.23719562 | C17: =$H$3*(1+$H$1)*(A17^($H$1))*EXP(-$H$3*(A17^(1+$H$1))) -> 0.26817859 | D17: =B17-C17 -> -0.030982965 | E17: =D17^2 -> 0.00095994415
... A40: 4.0320949 | B40: 0.00061769694 | C40: =$H$3*(1+$H$1)*(A40^($H$1))*EXP(-$H$3*(A40^(1+$H$1))) -> 0.00069340842 | D40: =B40-C40 -> -7.5711485e-05 | E40: =D40^2 -> 5.7322289e-09

Sheet 0.4
A1: 0.058334042 | B1: 0.10634228 | C1: =$H$3*(1+$H$1)*(A1^($H$1))*EXP(-$H$3*(A1^(1+$H$1))) -> 0.17023068 | D1: =B1-C1 -> -0.063888407 | E1: =D1^2 -> 0.0040817286 | G1: b | H1: 0.74615308
A2: 0.15583883 | B2: 0.3338503 | C2: =$H$3*(1+$H$1)*(A2^($H$1))*EXP(-$H$3*(A2^(1+$H$1))) -> 0.34524803 | D2: =B2-C2 -> -0.011397737 | E2: =D2^2 -> 0.00012990841
A3: 0.25334361 | B3: 0.49433046 | C3: =$H$3*(1+$H$1)*(A3^($H$1))*EXP(-$H$3*(A3^(1+$H$1))) -> 0.47548581 | D3: =B3-C3 -> 0.018844648 | E3: =D3^2 -> 0.00035512077 | G3: a_b | H3: =(_xlfn.GAMMA((2+$H$1)/(1+$H$1)))^(1+$H$1) -> 0.81705359
A4: 0.3508484 | B4: 0.58262677 | C4: =$H$3*(1+$H$1)*(A4^($H$1))*EXP(-$H$3*(A4^(1+$H$1))) -> 0.57271632 | D4: =B4-C4 -> 0.0099104472 | E4: =D4^2 -> 9.8216963e-05
A5: 0.44835318 | B5: 0.71732699 | C5: =$H$3*(1+$H$1)*(A5^($H$1))*EXP(-$H$3*(A5^(1+$H$1))) -> 0.64113306 | D5: =B5-C5 -> 0.076193926 | E5: =D5^2 -> 0.0058055143 | G5: SUM | H5: =SUM(E1:E40) -> 0.028801905
A6: 0.54585797 | B6: 0.73923994 | C6: =$H$3*(1+$H$1)*(A6^($H$1))*EXP(-$H$3*(A6^(1+$H$1))) -> 0.68369407 | D6: =B6-C6 -> 0.055545874 | E6: =D6^2 -> 0.0030853441
A7: 0.64336276 | B7: 0.73279495 | C7: =$H$3*(1+$H$1)*(A7^($H$1))*EXP(-$H$3*(A7^(1+$H$1))) -> 0.70329475 | D7: =B7-C7 -> 0.029500205 | E7: =D7^2 -> 0.00087026212
A8: 0.74086754 | B8: 0.6612556 | C8: =$H$3*(1+$H$1)*(A8^($H$1))*EXP(-$H$3*(A8^(1+$H$1))) -> 0.70301396 | D8: =B8-C8 -> -0.041758359 | E8: =D8^2 -> 0.0017437606
A9: 0.83837233 | B9: 0.67479008 | C9: =$H$3*(1+$H$1)*(A9^($H$1))*EXP(-$H$3*(A9^(1+$H$1))) -> 0.68609335 | D9: =B9-C9 -> -0.011303275 | E9: =D9^2 -> 0.00012776403
A10: 0.93587711 | B10: 0.65029913 | C10: =$H$3*(1+$H$1)*(A10^($H$1))*EXP(-$H$3*(A10^(1+$H$1))) -> 0.65582982 | D10: =B10-C10 -> -0.0055306908 | E10: =D10^2 -> 3.058854e-05
A11: 1.0333819 | B11: 0.60389523 | C11: =$H$3*(1+$H$1)*(A11^($H$1))*EXP(-$H$3*(A11^(1+$H$1))) -> 0.61544776 | D11: =B11-C11 -> -0.011552535 | E11: =D11^2 -> 0.00013346106
A12: 1.1308867 | B12: 0.59938374 | C12: =$H$3*(1+$H$1)*(A12^($H$1))*EXP(-$H$3*(A12^(1+$H$1))) -> 0.56798047 | D12: =B12-C12 -> 0.031403263 | E12: =D12^2 -> 0.00098616491
A13: 1.2283915 | B13: 0.57295929 | C13: =$H$3*(1+$H$1)*(A13^($H$1))*EXP(-$H$3*(A13^(1+$H$1))) -> 0.51617453 | D13: =B13-C13 -> 0.056784764 | E13: =D13^2 -> 0.0032245095
A14: 1.3258963 | B14: 0.44857105 | C14: =$H$3*(1+$H$1)*(A14^($H$1))*EXP(-$H$3*(A14^(1+$H$1))) -> 0.46242268 | D14: =B14-C14 -> -0.013851623 | E14: =D14^2 -> 0.00019186745
A15: 1.423401 | B15: 0.37316471 | C15: =$H$3*(1+$H$1)*(A15^($H$1))*EXP(-$H$3*(A15^(1+$H$1))) -> 0.40872597 | D15: =B15-C15 -> -0.035561262 | E15: =D15^2 -> 0.0012646034
A16: 1.5209058 | B16: 0.32289382 | C16: =$H$3*(1+$H$1)*(A16^($H$1))*EXP(-$H$3*(A16^(1+$H$1))) -> 0.35668274 | D16: =B16-C16 -> -0.033788917 | E16: =D16^2 -> 0.0011416909
A17: 1.6184106 | B17: 0.27262292 | C17: =$H$3*(1+$H$1)*(A17^($H$1))*EXP(-$H$3*(A17^(1+$H$1))) -> 0.30750014 | D17: =B17-C17 -> -0.034877216 | E17: =D17^2 -> 0.0012164202
... A40: 3.8610207 | B40: 0.00064449864 | C40: =$H$3*(1+$H$1)*(A40^($H$1))*EXP(-$H$3*(A40^(1+$H$1))) -> 0.00068864595 | D40: =B40-C40 -> -4.4147305e-05 | E40: =D40^2 -> 1.9489846e-09

Sheet 0.45
A1: 0.07675097 | B1: 0.10575352 | C1: =$H$3*(1+$H$1)*(A1^($H$1))*EXP(-$H$3*(A1^(1+$H$1))) -> 0.17780675 | D1: =B1-C1 -> -0.072053221 | E1: =D1^2 -> 0.0051916666 | G1: b | H1: 0.81942794
A2: 0.16945053 | B2: 0.30302452 | C2: =$H$3*(1+$H$1)*(A2^($H$1))*EXP(-$H$3*(A2^(1+$H$1))) -> 0.33205759 | D2: =B2-C2 -> -0.029033068 | E2: =D2^2 -> 0.00084291905
A3: 0.2621501 | B3: 0.48809319 | C3: =$H$3*(1+$H$1)*(A3^($H$1))*EXP(-$H$3*(A3^(1+$H$1))) -> 0.45676596 | D3: =B3-C3 -> 0.031327227 | E3: =D3^2 -> 0.00098139518 | G3: a_b | H3: =(_xlfn.GAMMA((2+$H$1)/(1+$H$1)))^(1+$H$1) -> 0.80702872
A4: 0.35484966 | B4: 0.55995135 | C4: =$H$3*(1+$H$1)*(A4^($H$1))*EXP(-$H$3*(A4^(1+$H$1))) -> 0.5557832 | D4: =B4-C4 -> 0.0041681511 | E4: =D4^2 -> 1.7373483e-05
A5: 0.44754922 | B5: 0.71925955 | C5: =$H$3*(1+$H$1)*(A5^($H$1))*EXP(-$H$3*(A5^(1+$H$1))) -> 0.63029171 | D5: =B5-C5 -> 0.088967832 | E5: =D5^2 -> 0.0079152751 | G5: SUM | H5: =SUM(E1:E40) -> 0.032762168
A6: 0.54024879 | B6: 0.73146188 | C6: =$H$3*(1+$H$1)*(A6^($H$1))*EXP(-$H$3*(A6^(1+$H$1))) -> 0.68136091 | D6: =B6-C6 -> 0.050100965 | E6: =D6^2 -> 0.0025101067
A7: 0.63294835 | B7: 0.77349212 | C7: =$H$3*(1+$H$1)*(A7^($H$1))*EXP(-$H$3*(A7^(1+$H$1))) -> 0.71048822 | D7: =B7-C7 -> 0.063003901 | E7: =D7^2 -> 0.0039694916
A8: 0.72564791 | B8: 0.7145142 | C8: =$H$3*(1+$H$1)*(A8^($H$1))*EXP(-$H$3*(A8^(1+$H$1))) -> 0.7196833 | D8: =B8-C8 -> -0.0051691025 | E8: =D8^2 -> 2.671962e-05
A9: 0.81834747 | B9: 0.70231187 | C9: =$H$3*(1+$H$1)*(A9^($H$1))*EXP(-$H$3*(A9^(1+$H$1))) -> 0.71139541 | D9: =B9-C9 -> -0.009083543 | E9: =D9^2 -> 8.2510754e-05
A10: 0.91104704 | B10: 0.65350255 | C10: =$H$3*(1+$H$1)*(A10^($H$1))*EXP(-$H$3*(A10^(1+$H$1))) -> 0.68837939 | D10: =B10-C10 -> -0.034876838 | E10: =D10^2 -> 0.0012163939
A11: 1.0037466 | B11: 0.62503044 | C11: =$H$3*(1+$H$1)*(A11^($H$1))*EXP(-$H$3*(A11^(1+$H$1))) -> 0.65354233 | D11: =B11-C11 -> -0.02851189 | E11: =D11^2 -> 0.00081292785
A12: 1.0964462 | B12: 0.6392665 | C12: =$H$3*(1+$H$1)*(A12^($H$1))*EXP(-$H$3*(A12^(1+$H$1))) -> 0.60979426 | D12: =B12-C12 -> 0.029472237 | E12: =D12^2 -> 0.00086861275
A13: 1.1891457 | B13: 0.58096648 | C13: =$H$3*(1+$H$1)*(A13^($H$1))*EXP(-$H$3*(A13^(1+$H$1))) -> 0.55991646 | D13: =B13-C13 -> 0.021050019 | E13: =D13^2 -> 0.00044310332
A14: 1.2818453 | B14: 0.52334436 | C14: =$H$3*(1+$H$1)*(A14^($H$1))*EXP(-$H$3*(A14^(1+$H$1))) -> 0.50645568 | D14: =B14-C14 -> 0.016888686 | E14: =D14^2 -> 0.00028522773
A15: 1.3745449 | B15: 0.45080829 | C15: =$H$3*(1+$H$1)*(A15^($H$1))*EXP(-$H$3*(A15^(1+$H$1))) -> 0.45164772 | D15: =B15-C15 -> -0.00083942853 | E15: =D15^2 -> 7.0464025e-07
A16: 1.4672444 | B16: 0.36064663 | C16: =$H$3*(1+$H$1)*(A16^($H$1))*EXP(-$H$3*(A16^(1+$H$1))) -> 0.39737082 | D16: =B16-C16 -> -0.036724189 | E16: =D16^2 -> 0.0013486661
A17: 1.559944 | B17: 0.31183732 | C17: =$H$3*(1+$H$1)*(A17^($H$1))*EXP(-$H$3*(A17^(1+$H$1))) -> 0.34512667 | D17: =B17-C17 -> -0.03328936 | E17: =D17^2 -> 0.0011081815
... A40: 3.6920339 | B40: 0.00067790721 | C40: =$H$3*(1+$H$1)*(A40^($H$1))*EXP(-$H$3*(A40^(1+$H$1))) -> 0.00072096484 | D40: =B40-C40 -> -4.3057633e-05 | E40: =D40^2 -> 1.8539598e-09

Sheet 0.5
A1: 0.076722184 | B1: 0.063287767 | C1: =$H$3*(1+$H$1)*(A1^($H$1))*EXP(-$H$3*(A1^(1+$H$1))) -> 0.14806804 | D1: =B1-C1 -> -0.084780275 | E1: =D1^2 -> 0.0071876951 | G1: b | H1: 0.90368189
A2: 0.16509489 | B2: 0.24248459 | C2: =$H$3*(1+$H$1)*(A2^($H$1))*EXP(-$H$3*(A2^(1+$H$1))) -> 0.29014271 | D2: =B2-C2 -> -0.04765812 | E2: =D2^2 -> 0.0022712964
A3: 0.2534676 | B3: 0.41457043 | C3: =$H$3*(1+$H$1)*(A3^($H$1))*EXP(-$H$3*(A3^(1+$H$1))) -> 0.41373119 | D3: =B3-C3 -> 0.00083924127 | E3: =D3^2 -> 7.0432591e-07 | G3: a_b | H3: =(_xlfn.GAMMA((2+$H$1)/(1+$H$1)))^(1+$H$1) -> 0.79643608
A4: 0.34184031 | B4: 0.58096748 | C4: =$H$3*(1+$H$1)*(A4^($H$1))*EXP(-$H$3*(A4^(1+$H$1))) -> 0.51838054 | D4: =B4-C4 -> 0.062586939 | E4: =D4^2 -> 0.0039171249
A5: 0.43021302 | B5: 0.62007789 | C5: =$H$3*(1+$H$1)*(A5^($H$1))*EXP(-$H$3*(A5^(1+$H$1))) -> 0.60294219 | D5: =B5-C5 -> 0.0171357 | E5: =D5^2 -> 0.00029363222 | G5: SUM | H5: =SUM(E1:E40) -> 0.041700149
A6: 0.51858573 | B6: 0.77651956 | C6: =$H$3*(1+$H$1)*(A6^($H$1))*EXP(-$H$3*(A6^(1+$H$1))) -> 0.66671543 | D6: =B6-C6 -> 0.10980413 | E6: =D6^2 -> 0.012056947
A7: 0.60695844 | B7: 0.76443089 | C7: =$H$3*(1+$H$1)*(A7^($H$1))*EXP(-$H$3*(A7^(1+$H$1))) -> 0.70972105 | D7: =B7-C7 -> 0.054709844 | E7: =D7^2 -> 0.002993167
A8: 0.69533115 | B8: 0.78149725 | C8: =$H$3*(1+$H$1)*(A8^($H$1))*EXP(-$H$3*(A8^(1+$H$1))) -> 0.73273772 | D8: =B8-C8 -> 0.048759538 | E8: =D8^2 -> 0.0023774926
A9: 0.78370386 | B9: 0.7587421 | C9: =$H$3*(1+$H$1)*(A9^($H$1))*EXP(-$H$3*(A9^(1+$H$1))) -> 0.73723319 | D9: =B9-C9 -> 0.021508914 | E9: =D9^2 -> 0.0004626334
A10: 0.87207657 | B10: 0.68336566 | C10: =$H$3*(1+$H$1)*(A10^($H$1))*EXP(-$H$3*(A10^(1+$H$1))) -> 0.72523847 | D10: =B10-C10 -> -0.041872813 | E10: =D10^2 -> 0.0017533324
A11: 0.96044928 | B11: 0.67909907 | C11: =$H$3*(1+$H$1)*(A11^($H$1))*EXP(-$H$3*(A11^(1+$H$1))) -> 0.69919218 | D11: =B11-C11 -> -0.020093106 | E11: =D11^2 -> 0.0004037329
A12: 1.048822 | B12: 0.65492172 | C12: =$H$3*(1+$H$1)*(A12^($H$1))*EXP(-$H$3*(A12^(1+$H$1))) -> 0.66177435 | D12: =B12-C12 -> -0.0068526247 | E12: =D12^2 -> 4.6958466e-05
A13: 1.1371947 | B13: 0.59945604 | C13: =$H$3*(1+$H$1)*(A13^($H$1))*EXP(-$H$3*(A13^(1+$H$1))) -> 0.61574505 | D13: =B13-C13 -> -0.016289012 | E13: =D13^2 -> 0.00026533191
A14: 1.2255674 | B14: 0.58238967 | C14: =$H$3*(1+$H$1)*(A14^($H$1))*EXP(-$H$3*(A14^(1+$H$1))) -> 0.56379925 | D14: =B14-C14 -> 0.01859042 | E14: =D14^2 -> 0.0003456037
A15: 1.3139401 | B15: 0.51625751 | C15: =$H$3*(1+$H$1)*(A15^($H$1))*EXP(-$H$3*(A15^(1+$H$1))) -> 0.50844617 | D15: =B15-C15 -> 0.0078113472 | E15: =D15^2 -> 6.1017146e-05
A16: 1.4023128 | B16: 0.43519228 | C16: =$H$3*(1+$H$1)*(A16^($H$1))*EXP(-$H$3*(A16^(1+$H$1))) -> 0.45191776 | D16: =B16-C16 -> -0.016725482 | E16: =D16^2 -> 0.00027974173
A17: 1.4906855 | B17: 0.36763793 | C17: =$H$3*(1+$H$1)*(A17^($H$1))*EXP(-$H$3*(A17^(1+$H$1))) -> 0.39610813 | D17: =B17-C17 -> -0.028470207 | E17: =D17^2 -> 0.0008105527
... A40: 3.5232579 | B40: 0.0007110985 | C40: =$H$3*(1+$H$1)*(A40^($H$1))*EXP(-$H$3*(A40^(1+$H$1))) -> 0.00074449046 | D40: =B40-C40 -> -3.3391963e-05 | E40: =D40^2 -> 1.1150232e-09

Sheet 0.55
A1: 0.086170122 | B1: 0.045001787 | C1: =$H$3*(1+$H$1)*(A1^($H$1))*EXP(-$H$3*(A1^(1+$H$1))) -> 0.13393695 | D1: =B1-C1 -> -0.088935159 | E1: =D1^2 -> 0.0079094624 | G1: b | H1: 1.002267
A2: 0.16995573 | B2: 0.20025795 | C2: =$H$3*(1+$H$1)*(A2^($H$1))*EXP(-$H$3*(A2^(1+$H$1))) -> 0.2601694 | D2: =B2-C2 -> -0.059911445 | E2: =D2^2 -> 0.0035893812
A3: 0.25374134 | B3: 0.36601454 | C3: =$H$3*(1+$H$1)*(A3^($H$1))*EXP(-$H$3*(A3^(1+$H$1))) -> 0.37812025 | D3: =B3-C3 -> -0.012105715 | E3: =D3^2 -> 0.00014654832 | G3: a_b | H3: =(_xlfn.GAMMA((2+$H$1)/(1+$H$1)))^(1+$H$1) -> 0.7851509
A4: 0.33752694 | B4: 0.52577088 | C4: =$H$3*(1+$H$1)*(A4^($H$1))*EXP(-$H$3*(A4^(1+$H$1))) -> 0.48413119 | D4: =B4-C4 -> 0.041639697 | E4: =D4^2 -> 0.0017338643
A5: 0.42131255 | B5: 0.63977541 | C5: =$H$3*(1+$H$1)*(A5^($H$1))*EXP(-$H$3*(A5^(1+$H$1))) -> 0.57520201 | D5: =B5-C5 -> 0.064573402 | E5: =D5^2 -> 0.0041697243 | G5: SUM | H5: =SUM(E1:E40) -> 0.050805767
A6: 0.50509816 | B6: 0.68627726 | C6: =$H$3*(1+$H$1)*(A6^($H$1))*EXP(-$H$3*(A6^(1+$H$1))) -> 0.64911122 | D6: =B6-C6 -> 0.037166042 | E6: =D6^2 -> 0.0013813147
A7: 0.58888377 | B7: 0.80028179 | C7: =$H$3*(1+$H$1)*(A7^($H$1))*EXP(-$H$3*(A7^(1+$H$1))) -> 0.70449265 | D7: =B7-C7 -> 0.09578914 | E7: =D7^2 -> 0.0091755594
A8: 0.67266938 | B8: 0.83103301 | C8: =$H$3*(1+$H$1)*(A8^($H$1))*EXP(-$H$3*(A8^(1+$H$1))) -> 0.74085629 | D8: =B8-C8 -> 0.090176718 | E8: =D8^2 -> 0.0081318404
A9: 0.75645498 | B9: 0.80028179 | C9: =$H$3*(1+$H$1)*(A9^($H$1))*EXP(-$H$3*(A9^(1+$H$1))) -> 0.75855314 | D9: =B9-C9 -> 0.041728644 | E9: =D9^2 -> 0.0017412798
A10: 0.84024059 | B10: 0.78228107 | C10: =$H$3*(1+$H$1)*(A10^($H$1))*EXP(-$H$3*(A10^(1+$H$1))) -> 0.75868993 | D10: =B10-C10 -> 0.02359114 | E10: =D10^2 -> 0.0005565419
A11: 0.9240262 | B11: 0.68852735 | C11: =$H$3*(1+$H$1)*(A11^($H$1))*EXP(-$H$3*(A11^(1+$H$1))) -> 0.74300372 | D11: =B11-C11 -> -0.054476371 | E11: =D11^2 -> 0.002967675
A12: 1.0078118 | B12: 0.69077744 | C12: =$H$3*(1+$H$1)*(A12^($H$1))*EXP(-$H$3*(A12^(1+$H$1))) -> 0.71370898 | D12: =B12-C12 -> -0.022931541 | E12: =D12^2 -> 0.00052585555
A13: 1.0915974 | B13: 0.65402598 | C13: =$H$3*(1+$H$1)*(A13^($H$1))*EXP(-$H$3*(A13^(1+$H$1))) -> 0.67333092 | D13: =B13-C13 -> -0.019304945 | E13: =D13^2 -> 0.00037268092
A14: 1.175383 | B14: 0.62102467 | C14: =$H$3*(1+$H$1)*(A14^($H$1))*EXP(-$H$3*(A14^(1+$H$1))) -> 0.6245386 | D14: =B14-C14 -> -0.0035139365 | E14: =D14^2 -> 1.234775e-05
A15: 1.2591686 | B15: 0.54977184 | C15: =$H$3*(1+$H$1)*(A15^($H$1))*EXP(-$H$3*(A15^(1+$H$1))) -> 0.56998975 | D15: =B15-C15 -> -0.020217915 | E15: =D15^2 -> 0.00040876407
A16: 1.3429542 | B16: 0.50777017 | C16: =$H$3*(1+$H$1)*(A16^($H$1))*EXP(-$H$3*(A16^(1+$H$1))) -> 0.51219697 | D16: =B16-C16 -> -0.004426799 | E16: =D16^2 -> 1.9596549e-05
A17: 1.4267398 | B17: 0.45751817 | C17: =$H$3*(1+$H$1)*(A17^($H$1))*EXP(-$H$3*(A17^(1+$H$1))) -> 0.45342181 | D17: =B17-C17 -> 0.0040963654 | E17: =D17^2 -> 1.678021e-05
... A40: 3.3538088 | B40: 0.0015000596 | C40: =$H$3*(1+$H$1)*(A40^($H$1))*EXP(-$H$3*(A40^(1+$H$1))) -> 0.00075376989 | D40: =B40-C40 -> 0.00074628969 | E40: =D40^2 -> 5.569483e-07

Sheet 0.6
A1: 0.10307105 | B1: 0.035815041 | C1: =$H$3*(1+$H$1)*(A1^($H$1))*EXP(-$H$3*(A1^(1+$H$1))) -> 0.12865292 | D1: =B1-C1 -> -0.092837884 | E1: =D1^2 -> 0.0086188727 | G1: b | H1: 1.1165137
A2: 0.18202885 | B2: 0.16315741 | C2: =$H$3*(1+$H$1)*(A2^($H$1))*EXP(-$H$3*(A2^(1+$H$1))) -> 0.23922985 | D2: =B2-C2 -> -0.076072446 | E2: =D2^2 -> 0.0057870171
A3: 0.26098664 | B3: 0.32472304 | C3: =$H$3*(1+$H$1)*(A3^($H$1))*EXP(-$H$3*(A3^(1+$H$1))) -> 0.34921079 | D3: =B3-C3 -> -0.02448776 | E3: =D3^2 -> 0.00059965037 | G3: a_b | H3: =(_xlfn.GAMMA((2+$H$1)/(1+$H$1)))^(1+$H$1) -> 0.77336249
A4: 0.33994443 | B4: 0.48071743 | C4: =$H$3*(1+$H$1)*(A4^($H$1))*EXP(-$H$3*(A4^(1+$H$1))) -> 0.4535095 | D4: =B4-C4 -> 0.027207938 | E4: =D4^2 -> 0.00074027191
A5: 0.41890223 | B5: 0.61920226 | C5: =$H$3*(1+$H$1)*(A5^($H$1))*EXP(-$H$3*(A5^(1+$H$1))) -> 0.54806542 | D5: =B5-C5 -> 0.071136838 | E5: =D5^2 -> 0.0050604497 | G5: SUM | H5: =SUM(E1:E40) -> 0.068550479
A6: 0.49786002 | B6: 0.69003645 | C6: =$H$3*(1+$H$1)*(A6^($H$1))*EXP(-$H$3*(A6^(1+$H$1))) -> 0.6296049 | D6: =B6-C6 -> 0.06043155 | E6: =D6^2 -> 0.0036519723
A7: 0.57681781 | B7: 0.79668568 | C7: =$H$3*(1+$H$1)*(A7^($H$1))*EXP(-$H$3*(A7^(1+$H$1))) -> 0.69564977 | D7: =B7-C7 -> 0.10103592 | E7: =D7^2 -> 0.010208256
A8: 0.65577561 | B8: 0.82533771 | C8: =$H$3*(1+$H$1)*(A8^($H$1))*EXP(-$H$3*(A8^(1+$H$1))) -> 0.7445624 | D8: =B8-C8 -> 0.080775316 | E8: =D8^2 -> 0.0065246516
A9: 0.7347334 | B9: 0.84523496 | C9: =$H$3*(1+$H$1)*(A9^($H$1))*EXP(-$H$3*(A9^(1+$H$1))) -> 0.77556886 | D9: =B9-C9 -> 0.069666095 | E9: =D9^2 -> 0.0048533648
A10: 0.81369119 | B10: 0.84762263 | C10: =$H$3*(1+$H$1)*(A10^($H$1))*EXP(-$H$3*(A10^(1+$H$1))) -> 0.78874034 | D10: =B10-C10 -> 0.058882294 | E10: =D10^2 -> 0.0034671245
A11: 0.89264899 | B11: 0.77042132 | C11: =$H$3*(1+$H$1)*(A11^($H$1))*EXP(-$H$3*(A11^(1+$H$1))) -> 0.78492827 | D11: =B11-C11 -> -0.014506954 | E11: =D11^2 -> 0.00021045172
A12: 0.97160678 | B12: 0.71948437 | C12: =$H$3*(1+$H$1)*(A12^($H$1))*EXP(-$H$3*(A12^(1+$H$1))) -> 0.76565721 | D12: =B12-C12 -> -0.046172836 | E12: =D12^2 -> 0.0021319307
A13: 1.0505646 | B13: 0.72585149 | C13: =$H$3*(1+$H$1)*(A13^($H$1))*EXP(-$H$3*(A13^(1+$H$1))) -> 0.73298418 | D13: =B13-C13 -> -0.0071326933 | E13: =D13^2 -> 5.0875314e-05
A14: 1.1295224 | B14: 0.63989539 | C14: =$H$3*(1+$H$1)*(A14^($H$1))*EXP(-$H$3*(A14^(1+$H$1))) -> 0.68933707 | D14: =B14-C14 -> -0.04944168 | E14: =D14^2 -> 0.0024444797
A15: 1.2084802 | B15: 0.63591594 | C15: =$H$3*(1+$H$1)*(A15^($H$1))*EXP(-$H$3*(A15^(1+$H$1))) -> 0.63734524 | D15: =B15-C15 -> -0.0014292993 | E15: =D15^2 -> 2.0428964e-06
A16: 1.287438 | B16: 0.54757218 | C16: =$H$3*(1+$H$1)*(A16^($H$1))*EXP(-$H$3*(A16^(1+$H$1))) -> 0.57967575 | D16: =B16-C16 -> -0.032103578 | E16: =D16^2 -> 0.0010306397
A17: 1.3663957 | B17: 0.50061468 | C17: =$H$3*(1+$H$1)*(A17^($H$1))*EXP(-$H$3*(A17^(1+$H$1))) -> 0.51888658 | D17: =B17-C17 -> -0.018271902 | E17: =D17^2 -> 0.0003338624
... A40: 3.182425 | B40: 0.0015917796 | C40: =$H$3*(1+$H$1)*(A40^($H$1))*EXP(-$H$3*(A40^(1+$H$1))) -> 0.00076302989 | D40: =B40-C40 -> 0.00082874969 | E40: =D40^2 -> 6.8682606e-07

Sheet 0.65
A1: 0.13084998 | B1: 0.034075141 | C1: =$H$3*(1+$H$1)*(A1^($H$1))*EXP(-$H$3*(A1^(1+$H$1))) -> 0.1336008 | D1: =B1-C1 -> -0.099525662 | E1: =D1^2 -> 0.0099053573 | G1: b | H1: 1.2504989
A2: 0.20461836 | B2: 0.14737499 | C2: =$H$3*(1+$H$1)*(A2^($H$1))*EXP(-$H$3*(A2^(1+$H$1))) -> 0.23052603 | D2: =B2-C2 -> -0.083151042 | E2: =D2^2 -> 0.0069140958
A3: 0.27838675 | B3: 0.30582439 | C3: =$H$3*(1+$H$1)*(A3^($H$1))*EXP(-$H$3*(A3^(1+$H$1))) -> 0.33160604 | D3: =B3-C3 -> -0.025781642 | E3: =D3^2 -> 0.00066469308 | G3: a_b | H3: =(_xlfn.GAMMA((2+$H$1)/(1+$H$1)))^(1+$H$1) -> 0.76103368
A4: 0.35215513 | B4: 0.4165686 | C4: =$H$3*(1+$H$1)*(A4^($H$1))*EXP(-$H$3*(A4^(1+$H$1))) -> 0.43183295 | D4: =B4-C4 -> -0.015264348 | E4: =D4^2 -> 0.00023300032
A5: 0.42592351 | B5: 0.59972249 | C5: =$H$3*(1+$H$1)*(A5^($H$1))*EXP(-$H$3*(A5^(1+$H$1))) -> 0.52692052 | D5: =B5-C5 -> 0.072801971 | E5: =D5^2 -> 0.005300127 | G5: SUM | H5: =SUM(E1:E40) -> 0.084861617
A6: 0.49969189 | B6: 0.70450355 | C6: =$H$3*(1+$H$1)*(A6^($H$1))*EXP(-$H$3*(A6^(1+$H$1))) -> 0.6131247 | D6: =B6-C6 -> 0.091378844 | E6: =D6^2 -> 0.0083500931
A7: 0.57346028 | B7: 0.78372825 | C7: =$H$3*(1+$H$1)*(A7^($H$1))*EXP(-$H$3*(A7^(1+$H$1))) -> 0.68727881 | D7: =B7-C7 -> 0.096449445 | E7: =D7^2 -> 0.0093024954
A8: 0.64722866 | B8: 0.85954544 | C8: =$H$3*(1+$H$1)*(A8^($H$1))*EXP(-$H$3*(A8^(1+$H$1))) -> 0.74688346 | D8: =B8-C8 -> 0.11266198 | E8: =D8^2 -> 0.012692722
A9: 0.72099704 | B9: 0.89362058 | C9: =$H$3*(1+$H$1)*(A9^($H$1))*EXP(-$H$3*(A9^(1+$H$1))) -> 0.79019357 | D9: =B9-C9 -> 0.10342701 | E9: =D9^2 -> 0.010697147
A10: 0.79476543 | B10: 0.87487926 | C10: =$H$3*(1+$H$1)*(A10^($H$1))*EXP(-$H$3*(A10^(1+$H$1))) -> 0.81627481 | D10: =B10-C10 -> 0.058604443 | E10: =D10^2 -> 0.0034344807
A11: 0.86853381 | B11: 0.84250787 | C11: =$H$3*(1+$H$1)*(A11^($H$1))*EXP(-$H$3*(A11^(1+$H$1))) -> 0.8250159 | D11: =B11-C11 -> 0.017491971 | E11: =D11^2 -> 0.00030596906
